Workbook
Name Allarmi: 'Classi allarmi RMT-STIG'!$E$1:$P$1014
Name Allarmi: #REF!
Name Modulo: OFFSET([1]Tendine!$B$3,0,0,COUNTA([1]Tendine!$B$3:$B$30),1)
Name Stato: OFFSET([1]Tendine!$P$3,0,0,COUNTA([1]Tendine!$P$3:$P$22),1)
Name Tecnologia: OFFSET([1]Tendine!$H$3,0,0,COUNTA([1]Tendine!$H$3:$H$29),1)
Name TecnologiaAID: OFFSET([1]Tendine!$L$3,0,0,COUNTA([1]Tendine!$L$3:$L$30),1)
Name TecnologiaLetturaTarghe: OFFSET([1]Tendine!$N$3,0,0,COUNTA([1]Tendine!$N$3:$N$30),1)
Name TecnologiaMeteo: OFFSET([1]Tendine!$J$3,0,0,COUNTA([1]Tendine!$J$3:$J$30),1)
Name TipoPP: OFFSET([1]Tendine!$F$3,0,0,COUNTA([1]Tendine!$F$3:$F$30),1)
Name WBSCluster: OFFSET([1]Tendine!$D$3,0,0,COUNTA([1]Tendine!$D$3:$D$30),1)

Sheet Classi allarmi RMT-STIG
A1: nome+descrizione | B1: CHECK nome+descrizione | C1: check nome | D1: check descriz. | E1: CATEGORIA ALLARME | F1: CODICE ALLARME | G1: DESCRIZIONE ALLARME | H1: IMPIANTO | I1: DISPOSITIVO | J1: PRESENTE IN PROCEDURA | K1: CHI VISUALIZZA L'ALLARME | L1: ID ISTRUZIONE OPERATIVA ALLARMI | M1: PRIORITÀ ALLARME | N1: COLORE NOTIFICA ALLARME | O1: ALLARME SONORO RMT | P1: NOTE
A2: =CONCATENATE(F2,"-",G2) -> ALL_PLC_RACK-Allarme plc rack | B2: =VLOOKUP(A2,'EXPORT IRIS PROD 13-11-2024'!A:A,1,0) -> ALL_PLC_RACK-Allarme plc rack | C2: =VLOOKUP(F2,'EXPORT IRIS PROD 13-11-2024'!F:F,1,0) -> ALL_PLC_RACK | D2: =VLOOKUP(G2,'EXPORT IRIS PROD 13-11-2024'!D:D,1,0) -> Allarme plc rack | E2: Impianto Rete dati-ANOMALIA | F2: ALL_PLC_RACK | G2: Allarme plc rack | H2: Impianto Rete dati | I2: Rack radio | J2: NO | K2: Impiantisti | L2: NA | M2: Bassa | N2: Blu | O2: NO
A3: =CONCATENATE(F3,"-",G3) -> ALLARME_DA_SOS-Allarme SOS premuto | B3: =VLOOKUP(A3,'EXPORT IRIS PROD 13-11-2024'!A:A,1,0) -> ALLARME_DA_SOS-Allarme SOS premuto | C3: =VLOOKUP(F3,'EXPORT IRIS PROD 13-11-2024'!F:F,1,0) -> ALLARME_DA_SOS | D3: =VLOOKUP(G3,'EXPORT IRIS PROD 13-11-2024'!D:D,1,0) -> Allarme SOS premuto | E3: Soccorso SOS | F3: ALLARME_DA_SOS | G3: Allarme SOS premuto | H3: Impianto SOS | I3: Colonnina Sos | J3: SI | K3: Sala operativa e Impiantisti | L3: 1 | M3: Alta | N3: Rosso | O3: SI
A4: =CONCATENATE(F4,"-",G4) -> ALLARME_GENERICO-allarme generico | B4: =VLOOKUP(A4,'EXPORT IRIS PROD 13-11-2024'!A:A,1,0) -> ALLARME_GENERICO-allarme generico | C4: =VLOOKUP(F4,'EXPORT IRIS PROD 13-11-2024'!F:F,1,0) -> ALLARME_GENERICO | D4: =VLOOKUP(G4,'EXPORT IRIS PROD 13-11-2024'!D:D,1,0) -> allarme generico | E4: Antincendio-ANOMALIA | F4: ALLARME_GENERICO | G4: allarme generico | H4: Impianto Antincendio | I4: Pompa | J4: NO | K4: Impiantisti | L4: NA | M4: Bassa | N4: Blu | O4: NO
A5: =CONCATENATE(F5,"-",G5) -> ALLARME_INCENDIO_CABINA-Allarme incendio in cabina | B5: =VLOOKUP(A5,'EXPORT IRIS PROD 13-11-2024'!A:A,1,0) -> ALLARME_INCENDIO_CABINA-Allarme incendio in cabina | C5: =VLOOKUP(F5,'EXPORT IRIS PROD 13-11-2024'!F:F,1,0) -> ALLARME_INCENDIO_CABINA | D5: =VLOOKUP(G5,'EXPORT IRIS PROD 13-11-2024'!D:D,1,0) -> Allarme incendio in cabina | E5: Incendio | F5: ALLARME_INCENDIO_CABINA | G5: Allarme incendio in cabina | H5: Impianto Rilevazione Incendio | I5: Centralina rilevazione incendio in cabina | J5: SI | K5: Sala operativa e Impiantisti | L5: 2 | M5: Altissima | N5: Viola | O5: SI
A6: =CONCATENATE(F6,"-",G6) -> ALLARME_INCENDIO_DA_SENSORE-Allarme incendio da sensori | B6: =VLOOKUP(A6,'EXPORT IRIS PROD 13-11-2024'!A:A,1,0) -> ALLARME_INCENDIO_DA_SENSORE-Allarme incendio da sensori | C6: =VLOOKUP(F6,'EXPORT IRIS PROD 13-11-2024'!F:F,1,0) -> ALLARME_INCENDIO_DA_SENSORE | D6: =VLOOKUP(G6,'EXPORT IRIS PROD 13-11-2024'!D:D,1,0) -> Allarme incendio da sensori | E6: Pre Allarme Incendio | F6: ALLARME_INCENDIO_DA_SENSORE | G6: Allarme incendio da sensori | H6: Impianto Ventilazione | I6: CO | J6: SI | K6: Sala operativa e Impiantisti | L6: 2 | M6: Altissima | N6: Viola | O6: SI
A7: =CONCATENATE(F7,"-",G7) -> ALLARME_INCENDIO_DA_SENSORE-Allarme incendio da sensori | B7: =VLOOKUP(A7,'EXPORT IRIS PROD 13-11-2024'!A:A,1,0) -> ALLARME_INCENDIO_DA_SENSORE-Allarme incendio da sensori | C7: =VLOOKUP(F7,'EXPORT IRIS PROD 13-11-2024'!F:F,1,0) -> ALLARME_INCENDIO_DA_SENSORE | D7: =VLOOKUP(G7,'EXPORT IRIS PROD 13-11-2024'!D:D,1,0) -> Allarme incendio da sensori | E7: Pre Allarme Incendio | F7: ALLARME_INCENDIO_DA_SENSORE | G7: Allarme incendio da sensori | H7: Impianto Ventilazione | I7: OP | J7: SI | K7: Sala operativa e Impiantisti | L7: 2 | M7: Altissima | N7: Viola | O7: SI
A8: =CONCATENATE(F8,"-",G8) -> ALR_1_GRUPPO_ELETTROGENO-Allarme centralina gestione elettronica GE - alarm1 | B8: =VLOOKUP(A8,'EXPORT IRIS PROD 13-11-2024'!A:A,1,0) -> ALR_1_GRUPPO_ELETTROGENO-Allarme centralina gestione elettronica GE - alarm1 | C8: =VLOOKUP(F8,'EXPORT IRIS PROD 13-11-2024'!F:F,1,0) -> ALR_1_GRUPPO_ELETTROGENO | D8: =VLOOKUP(G8,'EXPORT IRIS PROD 13-11-2024'!D:D,1,0) -> Allarme centralina gestione elettronica GE - alarm1 | E8: Impianto Elettrico-ANOMALIA | F8: ALR_1_GRUPPO_ELETTROGENO | G8: Allarme centralina gestione elettronica GE - alarm1 | H8: Impianto Elettrico | I8: Gruppo elettrogeno | J8: NO | K8: Impiantisti | L8: NA | M8: Bassa | N8: Blu | O8: NO
A9: =CONCATENATE(F9,"-",G9) -> ALR_113-Allarme SOS pulsante 113 | B9: =VLOOKUP(A9,'EXPORT IRIS PROD 13-11-2024'!A:A,1,0) -> ALR_113-Allarme SOS pulsante 113 | C9: =VLOOKUP(F9,'EXPORT IRIS PROD 13-11-2024'!F:F,1,0) -> ALR_113 | D9: =VLOOKUP(G9,'EXPORT IRIS PROD 13-11-2024'!D:D,1,0) -> Allarme SOS pulsante 113 | E9: Soccorso SOS | F9: ALR_113 | G9: Allarme SOS pulsante 113 | H9: Impianto SOS | I9: Colonnina Sos | J9: SI | K9: Sala operativa e Impiantisti | L9: 1 | M9: Alta | N9: Rosso | O9: SI
A10: =CONCATENATE(F10,"-",G10) -> ALR_115-Allarme SOS pulsante 115 | B10: =VLOOKUP(A10,'EXPORT IRIS PROD 13-11-2024'!A:A,1,0) -> ALR_115-Allarme SOS pulsante 115 | C10: =VLOOKUP(F10,'EXPORT IRIS PROD 13-11-2024'!F:F,1,0) -> ALR_115 | D10: =VLOOKUP(G10,'EXPORT IRIS PROD 13-11-2024'!D:D,1,0) -> Allarme SOS pulsante 115 | E10: Soccorso SOS | F10: ALR_115 | G10: Allarme SOS pulsante 115 | H10: Impianto SOS | I10: Colonnina Sos | J10: SI | K10: Sala operativa e Impiantisti | L10: 1 | M10: Alta | N10: Rosso | O10: SI
A11: =CONCATENATE(F11,"-",G11) -> ALR_118-Allarme SOS pulsante 118 | B11: =VLOOKUP(A11,'EXPORT IRIS PROD 13-11-2024'!A:A,1,0) -> ALR_118-Allarme SOS pulsante 118 | C11: =VLOOKUP(F11,'EXPORT IRIS PROD 13-11-2024'!F:F,1,0) -> ALR_118 | D11: =VLOOKUP(G11,'EXPORT IRIS PROD 13-11-2024'!D:D,1,0) -> Allarme SOS pulsante 118 | E11: Soccorso SOS | F11: ALR_118 | G11: Allarme SOS pulsante 118 | H11: Impianto SOS | I11: Colonnina Sos | J11: SI | K11: Sala operativa e Impiantisti | L11: 1 | M11: Alta | N11: Rosso | O11: SI
A12: =CONCATENATE(F12,"-",G12) -> ALR_2_GRUPPO_ELETTROGENO-Allarme centralina gestione elettronica GE - alarm2 | B12: =VLOOKUP(A12,'EXPORT IRIS PROD 13-11-2024'!A:A,1,0) -> ALR_2_GRUPPO_ELETTROGENO-Allarme centralina gestione elettronica GE - alarm2 | C12: =VLOOKUP(F12,'EXPORT IRIS PROD 13-11-2024'!F:F,1,0) -> ALR_2_GRUPPO_ELETTROGENO | D12: =VLOOKUP(G12,'EXPORT IRIS PROD 13-11-2024'!D:D,1,0) -> Allarme centralina gestione elettronica GE - alarm2 | E12: Impianto Elettrico-ANOMALIA | F12: ALR_2_GRUPPO_ELETTROGENO | G12: Allarme centralina gestione elettronica GE - alarm2 | H12: Impianto Elettrico | I12: Gruppo elettrogeno | J12: NO | K12: Impiantisti | L12: NA | M12: Bassa | N12: Blu | O12: NO
A13: =CONCATENATE(F13,"-",G13) -> ALR_800116-Allarme SOS soccorso meccanico_800116 | B13: =VLOOKUP(A13,'EXPORT IRIS PROD 13-11-2024'!A:A,1,0) -> ALR_800116-Allarme SOS soccorso meccanico_800116 | C13: =VLOOKUP(F13,'EXPORT IRIS PROD 13-11-2024'!F:F,1,0) -> ALR_800116 | D13: =VLOOKUP(G13,'EXPORT IRIS PROD 13-11-2024'!D:D,1,0) -> Allarme SOS soccorso meccanico_800116 | E13: Soccorso SOS | F13: ALR_800116 | G13: Allarme SOS soccorso meccanico_800116 | H13: Impianto SOS | I13: Colonnina Sos | J13: SI | K13: Sala operativa e Impiantisti | L13: 1 | M13: Alta | N13: Rosso | O13: SI
A14: =CONCATENATE(F14,"-",G14) -> ALR_803116-Allarme SOS soccorso meccanico_803116 | B14: =VLOOKUP(A14,'EXPORT IRIS PROD 13-11-2024'!A:A,1,0) -> ALR_803116-Allarme SOS soccorso meccanico_803116 | C14: =VLOOKUP(F14,'EXPORT IRIS PROD 13-11-2024'!F:F,1,0) -> ALR_803116 | D14: =VLOOKUP(G14,'EXPORT IRIS PROD 13-11-2024'!D:D,1,0) -> Allarme SOS soccorso meccanico_803116 | E14: Soccorso SOS | F14: ALR_803116 | G14: Allarme SOS soccorso meccanico_803116 | H14: Impianto SOS | I14: Colonnina Sos | J14: SI | K14: Sala operativa e Impiantisti | L14: 1 | M14: Alta | N14: Rosso | O14: SI
A15: =CONCATENATE(F15,"-",G15) -> ALR_ALLAGAMENTO-Allarme Allagamento | B15: =VLOOKUP(A15,'EXPORT IRIS PROD 13-11-2024'!A:A,1,0) -> ALR_ALLAGAMENTO-Allarme Allagamento | C15: =VLOOKUP(F15,'EXPORT IRIS PROD 13-11-2024'!F:F,1,0) -> ALR_ALLAGAMENTO | D15: =VLOOKUP(G15,'EXPORT IRIS PROD 13-11-2024'!D:D,1,0) -> Allarme Allagamento | E15: Allagamento | F15: ALR_ALLAGAMENTO | G15: Allarme Allagamento | H15: Impianto Allagamento | I15: Sonda allagamento | J15: SI | K15: Sala operativa e Impiantisti | L15: 2 | M15: Alta | N15: Rosso | O15: SI
A16: =CONCATENATE(F16,"-",G16) -> ALR_ALTERNATORE_IN_SOVRACCARICO_C-Allarme alternatore in sovraccarico C | B16: =VLOOKUP(A16,'EXPORT IRIS PROD 13-11-2024'!A:A,1,0) -> ALR_ALTERNATORE_IN_SOVRACCARICO_C-Allarme alternatore in sovraccarico C | C16: =VLOOKUP(F16,'EXPORT IRIS PROD 13-11-2024'!F:F,1,0) -> ALR_ALTERNATORE_IN_SOVRACCARICO_C | D16: =VLOOKUP(G16,'EXPORT IRIS PROD 13-11-2024'!D:D,1,0) -> Allarme alternatore in sovraccarico C | E16: Impianto Elettrico-ANOMALIA | F16: ALR_ALTERNATORE_IN_SOVRACCARICO_C | G16: Allarme alternatore in sovraccarico C | H16: Impianto Elettrico | I16: Gruppo elettrogeno | J16: NO | K16: Impiantisti | L16: NA | M16: Bassa | N16: Blu | O16: NO
A17: =CONCATENATE(F17,"-",G17) -> ALR_ALTERNATORE_IN_SOVRACCARICO_L-Allarme alternatore in sovraccarico L | B17: =VLOOKUP(A17,'EXPORT IRIS PROD 13-11-2024'!A:A,1,0) -> ALR_ALTERNATORE_IN_SOVRACCARICO_L-Allarme alternatore in sovraccarico L | C17: =VLOOKUP(F17,'EXPORT IRIS PROD 13-11-2024'!F:F,1,0) -> ALR_ALTERNATORE_IN_SOVRACCARICO_L | D17: =VLOOKUP(G17,'EXPORT IRIS PROD 13-11-2024'!D:D,1,0) -> Allarme alternatore in sovraccarico L | E17: Impianto Elettrico-ANOMALIA | F17: ALR_ALTERNATORE_IN_SOVRACCARICO_L | G17: Allarme alternatore in sovraccarico L | H17: Impianto Elettrico | I17: Gruppo elettrogeno | J17: NO | K17: Impiantisti | L17: NA | M17: Bassa | N17: Blu | O17: NO
A18: =CONCATENATE(F18,"-",G18) -> ALR_ALTERNATORE_NON_ECCITATO-Allarme alternatore non eccitato | B18: =VLOOKUP(A18,'EXPORT IRIS PROD 13-11-2024'!A:A,1,0) -> ALR_ALTERNATORE_NON_ECCITATO-Allarme alternatore non eccitato | C18: =VLOOKUP(F18,'EXPORT IRIS PROD 13-11-2024'!F:F,1,0) -> ALR_ALTERNATORE_NON_ECCITATO | D18: =VLOOKUP(G18,'EXPORT IRIS PROD 13-11-2024'!D:D,1,0) -> Allarme alternatore non eccitato | E18: Impianto Elettrico-ANOMALIA | F18: ALR_ALTERNATORE_NON_ECCITATO | G18: Allarme alternatore non eccitato | H18: Impianto Elettrico | I18: Gruppo elettrogeno | J18: NO | K18: Impiantisti | L18: NA | M18: Bassa | N18: Blu | O18: NO
A19: =CONCATENATE(F19,"-",G19) -> ALR_ALTO_LIV_GASOLIO_SERB-Allarme livello gasolio alto | B19: =VLOOKUP(A19,'EXPORT IRIS PROD 13-11-2024'!A:A,1,0) -> ALR_ALTO_LIV_GASOLIO_SERB-Allarme livello gasolio alto | C19: =VLOOKUP(F19,'EXPORT IRIS PROD 13-11-2024'!F:F,1,0) -> ALR_ALTO_LIV_GASOLIO_SERB | D19: =VLOOKUP(G19,'EXPORT IRIS PROD 13-11-2024'!D:D,1,0) -> Allarme livello gasolio alto | E19: Impianto Elettrico-ANOMALIA | F19: ALR_ALTO_LIV_GASOLIO_SERB | G19: Allarme livello gasolio alto | H19: Impianto Elettrico | I19: Gruppo elettrogeno | J19: NO | K19: Impiantisti | L19: NA | M19: Bassa | N19: Blu | O19: NO
A20: =CONCATENATE(F20,"-",G20) -> ALR_ALTO_LIVELLO_POMPA-Allarme alto livello pompa | B20: =VLOOKUP(A20,'EXPORT IRIS PROD 13-11-2024'!A:A,1,0) -> ALR_ALTO_LIVELLO_POMPA-Allarme alto livello pompa | C20: =VLOOKUP(F20,'EXPORT IRIS PROD 13-11-2024'!F:F,1,0) -> ALR_ALTO_LIVELLO_POMPA | D20: =VLOOKUP(G20,'EXPORT IRIS PROD 13-11-2024'!D:D,1,0) -> Allarme alto livello pompa | E20: Antincendio-ANOMALIA | F20: ALR_ALTO_LIVELLO_POMPA | G20: Allarme alto livello pompa | H20: Impianto Antincendio | I20: Pompa | J20: NO | K20: Impiantisti | L20: NA | M20: Bassa | N20: Blu | O20: NO
A21: =CONCATENATE(F21,"-",G21) -> ALR_ANEMOMETRO-Allarme guasto anemometro | B21: =VLOOKUP(A21,'EXPORT IRIS PROD 13-11-2024'!A:A,1,0) -> ALR_ANEMOMETRO-Allarme guasto anemometro | C21: =VLOOKUP(F21,'EXPORT IRIS PROD 13-11-2024'!F:F,1,0) -> ALR_ANEMOMETRO | D21: =VLOOKUP(G21,'EXPORT IRIS PROD 13-11-2024'!D:D,1,0) -> Allarme guasto anemometro | E21: Ventilazione-ANOMALIA | F21: ALR_ANEMOMETRO | G21: Allarme guasto anemometro | H21: Impianto Ventilazione | I21: Anemometro | J21: NO | K21: Impiantisti | L21: NA | M21: Bassa | N21: Blu | O21: NO
A22: =CONCATENATE(F22,"-",G22) -> ALR_ANTA_ESTINTORE_APERTA-Allarme apertura anta estintore colonnina SOS | B22: =VLOOKUP(A22,'EXPORT IRIS PROD 13-11-2024'!A:A,1,0) -> ALR_ANTA_ESTINTORE_APERTA-Allarme apertura anta estintore colonnina SOS | C22: =VLOOKUP(F22,'EXPORT IRIS PROD 13-11-2024'!F:F,1,0) -> ALR_ANTA_ESTINTORE_APERTA | D22: =VLOOKUP(G22,'EXPORT IRIS PROD 13-11-2024'!D:D,1,0) -> Allarme apertura anta estintore colonnina SOS | E22: Impianto SOS-ANOMALIA | F22: ALR_ANTA_ESTINTORE_APERTA | G22: Allarme apertura anta estintore colonnina SOS | H22: Impianto SOS | I22: Colonnina Sos | J22: NO | K22: Impiantisti | L22: NA | M22: Bassa | N22: Blu | O22: NO
A23: =CONCATENATE(F23,"-",G23) -> ALR_ANTE_INFERIORI-Allarme ante inferiori | B23: =VLOOKUP(A23,'EXPORT IRIS PROD 13-11-2024'!A:A,1,0) -> ALR_ANTE_INFERIORI-Allarme ante inferiori | C23: =VLOOKUP(F23,'EXPORT IRIS PROD 13-11-2024'!F:F,1,0) -> ALR_ANTE_INFERIORI | D23: =VLOOKUP(G23,'EXPORT IRIS PROD 13-11-2024'!D:D,1,0) -> Allarme ante inferiori | E23: Impianto SOS-ANOMALIA | F23: ALR_ANTE_INFERIORI | G23: Allarme ante inferiori | H23: Impianto SOS | I23: Colonnina Sos | J23: NO | K23: Impiantisti | L23: NA | M23: Bassa | N23: Blu | O23: NO
A24: =CONCATENATE(F24,"-",G24) -> ALR_ANTE_SUPERIORI-Allarme ante superiori | B24: =VLOOKUP(A24,'EXPORT IRIS PROD 13-11-2024'!A:A,1,0) -> ALR_ANTE_SUPERIORI-Allarme ante superiori | C24: =VLOOKUP(F24,'EXPORT IRIS PROD 13-11-2024'!F:F,1,0) -> ALR_ANTE_SUPERIORI | D24: =VLOOKUP(G24,'EXPORT IRIS PROD 13-11-2024'!D:D,1,0) -> Allarme ante superiori | E24: Impianto SOS-ANOMALIA | F24: ALR_ANTE_SUPERIORI | G24: Allarme ante superiori | H24: Impianto SOS | I24: Colonnina Sos | J24: NO | K24: Impiantisti | L24: NA | M24: Bassa | N24: Blu | O24: NO
A25: =CONCATENATE(F25,"-",G25) -> ALR_APERTURA_IMMOTIVATA_GCB-Allarme apertura immotivata contattore generatore | B25: =VLOOKUP(A25,'EXPORT IRIS PROD 13-11-2024'!A:A,1,0) -> ALR_APERTURA_IMMOTIVATA_GCB-Allarme apertura immotivata contattore generatore | C25: =VLOOKUP(F25,'EXPORT IRIS PROD 13-11-2024'!F:F,1,0) -> ALR_APERTURA_IMMOTIVATA_GCB | D25: =VLOOKUP(G25,'EXPORT IRIS PROD 13-11-2024'!D:D,1,0) -> Allarme apertura immotivata contattore generatore | E25: Impianto Elettrico-ANOMALIA | F25: ALR_APERTURA_IMMOTIVATA_GCB | G25: Allarme apertura immotivata contattore generatore | H25: Impianto Elettrico | I25: Gruppo elettrogeno | J25: NO | K25: Impiantisti | L25: NA | M25: Bassa | N25: Blu | O25: NO
A26: =CONCATENATE(F26,"-",G26) -> ALR_APERTURA_IMMOTIVATA_MCB-Allarme apertura immotivata contattore di rete | B26: =VLOOKUP(A26,'EXPORT IRIS PROD 13-11-2024'!A:A,1,0) -> ALR_APERTURA_IMMOTIVATA_MCB-Allarme apertura immotivata contattore di rete | C26: =VLOOKUP(F26,'EXPORT IRIS PROD 13-11-2024'!F:F,1,0) -> ALR_APERTURA_IMMOTIVATA_MCB | D26: =VLOOKUP(G26,'EXPORT IRIS PROD 13-11-2024'!D:D,1,0) -> Allarme apertura immotivata contattore di rete | E26: Impianto Elettrico-ANOMALIA | F26: ALR_APERTURA_IMMOTIVATA_MCB | G26: Allarme apertura immotivata contattore di rete | H26: Impianto Elettrico | I26: Gruppo elettrogeno | J26: NO | K26: Impiantisti | L26: NA | M26: Bassa | N26: Blu | O26: NO
A27: =CONCATENATE(F27,"-",G27) -> ALR_ARRESTO_EMERGENZA-Allarme arresto Gruppo Elettrogeno | B27: =VLOOKUP(A27,'EXPORT IRIS PROD 13-11-2024'!A:A,1,0) -> ALR_ARRESTO_EMERGENZA-Allarme arresto Gruppo Elettrogeno | C27: =VLOOKUP(F27,'EXPORT IRIS PROD 13-11-2024'!F:F,1,0) -> ALR_ARRESTO_EMERGENZA | D27: =VLOOKUP(G27,'EXPORT IRIS PROD 13-11-2024'!D:D,1,0) -> Allarme arresto Gruppo Elettrogeno | E27: Impianto Elettrico-ANOMALIA | F27: ALR_ARRESTO_EMERGENZA | G27: Allarme arresto Gruppo Elettrogeno | H27: Impianto Elettrico | I27: Gruppo elettrogeno | J27: NO | K27: Impiantisti | L27: NA | M27: Bassa | N27: Blu | O27: NO
A28: =CONCATENATE(F28,"-",G28) -> ALR_ASSENZA_RETE-Allarme assenza rete | B28: =VLOOKUP(A28,'EXPORT IRIS PROD 13-11-2024'!A:A,1,0) -> ALR_ASSENZA_RETE-Allarme assenza rete | C28: =VLOOKUP(F28,'EXPORT IRIS PROD 13-11-2024'!F:F,1,0) -> ALR_ASSENZA_RETE | D28: =VLOOKUP(G28,'EXPORT IRIS PROD 13-11-2024'!D:D,1,0) -> Allarme assenza rete | E28: Impianto Elettrico-ANOMALIA | F28: ALR_ASSENZA_RETE | G28: Allarme assenza rete | H28: Impianto Elettrico | I28: UPS | J28: NO | K28: Impiantisti | L28: NA | M28: Bassa | N28: Blu | O28: NO
A29: =CONCATENATE(F29,"-",G29) -> ALR_ASSENZA_TENSIONE-Allarme assenza tensione dispositivo | B29: =VLOOKUP(A29,'EXPORT IRIS PROD 13-11-2024'!A:A,1,0) -> ALR_ASSENZA_TENSIONE-Allarme assenza tensione dispositivo | C29: =VLOOKUP(F29,'EXPORT IRIS PROD 13-11-2024'!F:F,1,0) -> ALR_ASSENZA_TENSIONE | D29: =VLOOKUP(G29,'EXPORT IRIS PROD 13-11-2024'!D:D,1,0) -> Allarme assenza tensione dispositivo | E29: Impianto Rilevazione Incendio-ANOMALIA | F29: ALR_ASSENZA_TENSIONE | G29: Allarme assenza tensione dispositivo | H29: Impianto Rilevazione Incendio | I29: Centralina rilevazione incendio | J29: SI | K29: Sala operativa e Impiantisti | L29: 3 | M29: Bassa | N29: Blu | O29: NO
A30: =CONCATENATE(F30,"-",G30) -> ALR_ASSENZA_TENSIONE_2_IMP-Allarme assenza tensione dispositivo | B30: =VLOOKUP(A30,'EXPORT IRIS PROD 13-11-2024'!A:A,1,0) -> ALR_ASSENZA_TENSIONE_2_IMP-Allarme assenza tensione dispositivo | C30: =VLOOKUP(F30,'EXPORT IRIS PROD 13-11-2024'!F:F,1,0) -> ALR_ASSENZA_TENSIONE_2_IMP | D30: =VLOOKUP(G30,'EXPORT IRIS PROD 13-11-2024'!D:D,1,0) -> Allarme assenza tensione dispositivo | E30: Canalizzazione-ANOMALIA | F30: ALR_ASSENZA_TENSIONE_2_IMP | G30: Allarme assenza tensione dispositivo | H30: Impianto Canalizzazione | I30: Rotocartello | J30: NO | K30: Impiantisti | L30: NA | M30: Bassa | N30: Blu | O30: NO
A31: =CONCATENATE(F31,"-",G31) -> ALR_ASSENZA_TENSIONE_2_IMP-Allarme assenza tensione dispositivo | B31: =VLOOKUP(A31,'EXPORT IRIS PROD 13-11-2024'!A:A,1,0) -> ALR_ASSENZA_TENSIONE_2_IMP-Allarme assenza tensione dispositivo | C31: =VLOOKUP(F31,'EXPORT IRIS PROD 13-11-2024'!F:F,1,0) -> ALR_ASSENZA_TENSIONE_2_IMP | D31: =VLOOKUP(G31,'EXPORT IRIS PROD 13-11-2024'!D:D,1,0) -> Allarme assenza tensione dispositivo | E31: Impianto Elettrico-ANOMALIA | F31: ALR_ASSENZA_TENSIONE_2_IMP | G31: Allarme assenza tensione dispositivo | H31: Impianto Elettrico | I31: Gruppo elettrogeno | J31: NO | K31: Impiantisti | L31: NA | M31: Bassa | N31: Blu | O31: NO
A32: =CONCATENATE(F32,"-",G32) -> ALR_ASSENZA_TENSIONE_2_IMP-Allarme assenza tensione dispositivo | B32: =VLOOKUP(A32,'EXPORT IRIS PROD 13-11-2024'!A:A,1,0) -> ALR_ASSENZA_TENSIONE_2_IMP-Allarme assenza tensione dispositivo | C32: =VLOOKUP(F32,'EXPORT IRIS PROD 13-11-2024'!F:F,1,0) -> ALR_ASSENZA_TENSIONE_2_IMP | D32: =VLOOKUP(G32,'EXPORT IRIS PROD 13-11-2024'!D:D,1,0) -> Allarme assenza tensione dispositivo | E32: Impianto Elettrico-ANOMALIA | F32: ALR_ASSENZA_TENSIONE_2_IMP | G32: Allarme assenza tensione dispositivo | H32: Impianto Elettrico | I32: Interruttore relè | J32: NO | K32: Impiantisti | L32: NA | M32: Bassa | N32: Blu | O32: NO
A33: =CONCATENATE(F33,"-",G33) -> ALR_ASSENZA_TENSIONE_2_IMP-Allarme assenza tensione dispositivo | B33: =VLOOKUP(A33,'EXPORT IRIS PROD 13-11-2024'!A:A,1,0) -> ALR_ASSENZA_TENSIONE_2_IMP-Allarme assenza tensione dispositivo | C33: =VLOOKUP(F33,'EXPORT IRIS PROD 13-11-2024'!F:F,1,0) -> ALR_ASSENZA_TENSIONE_2_IMP | D33: =VLOOKUP(G33,'EXPORT IRIS PROD 13-11-2024'!D:D,1,0) -> Allarme assenza tensione dispositivo | E33: Impianto Elettrico-ANOMALIA | F33: ALR_ASSENZA_TENSIONE_2_IMP | G33: Allarme assenza tensione dispositivo | H33: Impianto Elettrico | I33: Quadro elettrico | J33: NO | K33: Impiantisti | L33: NA | M33: Bassa | N33: Blu | O33: NO
A34: =CONCATENATE(F34,"-",G34) -> ALR_ASSENZA_TENSIONE_2_IMP-Allarme assenza tensione dispositivo | B34: =VLOOKUP(A34,'EXPORT IRIS PROD 13-11-2024'!A:A,1,0) -> ALR_ASSENZA_TENSIONE_2_IMP-Allarme assenza tensione dispositivo | C34: =VLOOKUP(F34,'EXPORT IRIS PROD 13-11-2024'!F:F,1,0) -> ALR_ASSENZA_TENSIONE_2_IMP | D34: =VLOOKUP(G34,'EXPORT IRIS PROD 13-11-2024'!D:D,1,0) -> Allarme assenza tensione dispositivo | E34: Illuminazione-ANOMALIA | F34: ALR_ASSENZA_TENSIONE_2_IMP | G34: Allarme assenza tensione dispositivo | H34: Impianto Illuminazione | I34: Guida led | J34: NO | K34: Impiantisti | L34: NA | M34: Bassa | N34: Blu | O34: NO
A35: =CONCATENATE(F35,"-",G35) -> ALR_ASSENZA_TENSIONE_2_IMP-Allarme assenza tensione dispositivo | B35: =VLOOKUP(A35,'EXPORT IRIS PROD 13-11-2024'!A:A,1,0) -> ALR_ASSENZA_TENSIONE_2_IMP-Allarme assenza tensione dispositivo | C35: =VLOOKUP(F35,'EXPORT IRIS PROD 13-11-2024'!F:F,1,0) -> ALR_ASSENZA_TENSIONE_2_IMP | D35: =VLOOKUP(G35,'EXPORT IRIS PROD 13-11-2024'!D:D,1,0) -> Allarme assenza tensione dispositivo | E35: Impianto SOS-ANOMALIA | F35: ALR_ASSENZA_TENSIONE_2_IMP | G35: Allarme assenza tensione dispositivo | H35: Impianto SOS | I35: Colonnina Sos | J35: NO | K35: Impiantisti | L35: NA | M35: Bassa | N35: Blu | O35: NO
A36: =CONCATENATE(F36,"-",G36) -> ALR_ASSIMETRIA_ALTERNATORE-Allarme assimetria alternatore | B36: =VLOOKUP(A36,'EXPORT IRIS PROD 13-11-2024'!A:A,1,0) -> ALR_ASSIMETRIA_ALTERNATORE-Allarme assimetria alternatore | C36: =VLOOKUP(F36,'EXPORT IRIS PROD 13-11-2024'!F:F,1,0) -> ALR_ASSIMETRIA_ALTERNATORE | D36: =VLOOKUP(G36,'EXPORT IRIS PROD 13-11-2024'!D:D,1,0) -> Allarme assimetria alternatore | E36: Impianto Elettrico-ANOMALIA | F36: ALR_ASSIMETRIA_ALTERNATORE | G36: Allarme assimetria alternatore | H36: Impianto Elettrico | I36: Gruppo elettrogeno | J36: NO | K36: Impiantisti | L36: NA | M36: Bassa | N36: Blu | O36: NO
A37: =CONCATENATE(F37,"-",G37) -> ALR_ASSIMETRIA_RETE-Allarme assimetria rete | B37: =VLOOKUP(A37,'EXPORT IRIS PROD 13-11-2024'!A:A,1,0) -> ALR_ASSIMETRIA_RETE-Allarme assimetria rete | C37: =VLOOKUP(F37,'EXPORT IRIS PROD 13-11-2024'!F:F,1,0) -> ALR_ASSIMETRIA_RETE | D37: =VLOOKUP(G37,'EXPORT IRIS PROD 13-11-2024'!D:D,1,0) -> Allarme assimetria rete | E37: Impianto Elettrico-ANOMALIA | F37: ALR_ASSIMETRIA_RETE | G37: Allarme assimetria rete | H37: Impianto Elettrico | I37: Gruppo elettrogeno | J37: NO | K37: Impiantisti | L37: NA | M37: Bassa | N37: Blu | O37: NO
A38: =CONCATENATE(F38,"-",G38) -> ALR_ASSIMETRIA_RETE-Allarme assimetria rete | B38: =VLOOKUP(A38,'EXPORT IRIS PROD 13-11-2024'!A:A,1,0) -> ALR_ASSIMETRIA_RETE-Allarme assimetria rete | C38: =VLOOKUP(F38,'EXPORT IRIS PROD 13-11-2024'!F:F,1,0) -> ALR_ASSIMETRIA_RETE | D38: =VLOOKUP(G38,'EXPORT IRIS PROD 13-11-2024'!D:D,1,0) -> Allarme assimetria rete | E38: Impianto Elettrico-ANOMALIA | F38: ALR_ASSIMETRIA_RETE | G38: Allarme assimetria rete | H38: Impianto Elettrico | I38: UPS | J38: NO | K38: Impiantisti | L38: NA | M38: Bassa | N38: Blu | O38: NO
A39: =CONCATENATE(F39,"-",G39) -> ALR_ASSORBIMENTO-Allarme assorbimento ventilatore | B39: =VLOOKUP(A39,'EXPORT IRIS PROD 13-11-2024'!A:A,1,0) -> ALR_ASSORBIMENTO-Allarme assorbimento ventilatore | C39: =VLOOKUP(F39,'EXPORT IRIS PROD 13-11-2024'!F:F,1,0) -> ALR_ASSORBIMENTO | D39: =VLOOKUP(G39,'EXPORT IRIS PROD 13-11-2024'!D:D,1,0) -> Allarme assorbimento ventilatore | E39: Ventilazione-ANOMALIA | F39: ALR_ASSORBIMENTO | G39: Allarme assorbimento ventilatore | H39: Impianto Ventilazione | I39: Ventilatore | J39: NO | K39: Impiantisti | L39: NA | M39: Bassa | N39: Blu | O39: NO
A40: =CONCATENATE(F40,"-",G40) -> ALR_AVARIA_ALIMENTATORI-Allarme avaria alimentatori | B40: =VLOOKUP(A40,'EXPORT IRIS PROD 13-11-2024'!A:A,1,0) -> ALR_AVARIA_ALIMENTATORI-Allarme avaria alimentatori | C40: =VLOOKUP(F40,'EXPORT IRIS PROD 13-11-2024'!F:F,1,0) -> ALR_AVARIA_ALIMENTATORI | D40: =VLOOKUP(G40,'EXPORT IRIS PROD 13-11-2024'!D:D,1,0) -> Allarme avaria alimentatori | E40: Canalizzazione-ANOMALIA | F40: ALR_AVARIA_ALIMENTATORI | G40: Allarme avaria alimentatori | H40: Impianto Canalizzazione | I40: PMV/Frecciacroce | J40: NO | K40: Impiantisti | L40: NA | M40: Bassa | N40: Blu | O40: NO
...

Sheet NEW-Allarmi
A1: nome+descrizione | B1: CHECK nome+descrizione | C1: AGR | D1: GALLERIA | E1: STRADA | F1: CATEGORIA ALLARME | G1: CODICE ALLARME | H1: DESCRIZIONE ALLARME | I1: IMPIANTO | J1: DISPOSITIVO | K1: PRESENTE IN PROCEDURA | L1: CHI VISUALIZZA L'ALLARME | M1: ID ISTRUZIONE OPERATIVA ALLARMI | N1: PRIORITÀ ALLARME | O1: COLORE NOTIFICA ALLARME | P1: ALLARME SONORO RMT | Q1: NOTE Sinelec al 09/08/2024 | R1: NOTE Sinelec al 08/10/2024 | S1: NOTE Sinelec al 21/10/2024
A2: =CONCATENATE(G2,"-",H2) -> ALR_AVARIA_INGRESSI_DIGITALI_PLC-Allarme avaria Scheda Ingressi Digitali PLC | B2: =VLOOKUP(A2,'EXPORT IRIS PROD 13-11-2024'!A:A,1,0) -> ALR_AVARIA_INGRESSI_DIGITALI_PLC-Allarme avaria Scheda Ingressi Digitali PLC | C2: Campania | D2: STARZE | E2: SS 18 VAR CILENTANA | F2: Impianto Rete dati-ANOMALIA | G2: ALR_AVARIA_INGRESSI_DIGITALI_PLC | H2: Allarme avaria Scheda Ingressi Digitali PLC | I2: Impianto rete dati | J2: PLC primario/di cabina | K2: NO | L2: Impiantisti | M2: NA | N2: Bassa | O2: Blu | P2: NO | Q2: Nuovo inserimento classe allarme
A3: =CONCATENATE(G3,"-",H3) -> ALR_AVARIA_USCITE_DIGITALI_PLC-Allarme avaria Scheda Uscite Digitali PLC | B3: =VLOOKUP(A3,'EXPORT IRIS PROD 13-11-2024'!A:A,1,0) -> ALR_AVARIA_USCITE_DIGITALI_PLC-Allarme avaria Scheda Uscite Digitali PLC | C3: Campania | D3: STARZE | E3: SS 18 VAR CILENTANA | F3: Impianto Rete dati-ANOMALIA | G3: ALR_AVARIA_USCITE_DIGITALI_PLC | H3: Allarme avaria Scheda Uscite Digitali PLC | I3: Impianto rete dati | J3: PLC primario/di cabina | K3: NO | L3: Impiantisti | M3: NA | N3: Bassa | O3: Blu | P3: NO | Q3: Nuovo inserimento classe allarme
A4: =CONCATENATE(G4,"-",H4) -> ALR_GUASTO_2_IMP-Allarme guasto dispositivo | B4: =VLOOKUP(A4,'EXPORT IRIS PROD 13-11-2024'!A:A,1,0) -> ALR_GUASTO_2_IMP-Allarme guasto dispositivo | C4: Piemonte | D4: VERTA | E4: SS 229 DEL LAGO D'ORTA | F4: Impianto Radio | G4: ALR_GUASTO_2_IMP | H4: Allarme guasto dispositivo | I4: Impianto radio | J4: Centrale sonora | K4: NO | L4: Impiantisti | M4: NA | N4: Bassa | O4: Blu | P4: NO | Q4: Nuova associazione classe-dispositivo
A5: =CONCATENATE(G5,"-",H5) -> ALR_AVVIAMENTO_IN_CORSO-Allarme avviamento in corso | B5: =VLOOKUP(A5,'EXPORT IRIS PROD 13-11-2024'!A:A,1,0) -> ALR_AVVIAMENTO_IN_CORSO-Allarme avviamento in corso | C5: Piemonte | D5: VERTA | E5: SS 229 DEL LAGO D'ORTA | F5: Impianto Elettrico-ANOMALIA | G5: ALR_AVVIAMENTO_IN_CORSO | H5: Allarme avviamento in corso | I5: Impianto Elettrico | J5: Gruppo elettrogeno | K5: NO | L5: Impiantisti | M5: NA | N5: Media | O5: Arancione | P5: NO | Q5: Nuovo inserimento classe allarme
A6: =CONCATENATE(G6,"-",H6) -> ALR_ARRESTO_IN_CORSO-Allarme arresto in corso | B6: =VLOOKUP(A6,'EXPORT IRIS PROD 13-11-2024'!A:A,1,0) -> ALR_ARRESTO_IN_CORSO-Allarme arresto in corso | C6: Piemonte | D6: VERTA | E6: SS 229 DEL LAGO D'ORTA | F6: Impianto Elettrico-ANOMALIA | G6: ALR_ARRESTO_IN_CORSO | H6: Allarme arresto in corso | I6: Impianto Elettrico | J6: Gruppo elettrogeno | K6: NO | L6: Impiantisti | M6: NA | N6: Media | O6: Arancione | P6: NO | Q6: Nuovo inserimento classe allarme
A7: =CONCATENATE(G7,"-",H7) -> ALR_FAULT_MODULO_1-Allarme fault modulo 1 | B7: =VLOOKUP(A7,'EXPORT IRIS PROD 13-11-2024'!A:A,1,0) -> ALR_FAULT_MODULO_1-Allarme fault modulo 1 | C7: Piemonte | D7: VERTA | E7: SS 229 DEL LAGO D'ORTA | F7: Impianto Rete dati-ANOMALIA | G7: ALR_FAULT_MODULO_1 | H7: Allarme fault modulo 1 | I7: Impianto Rete dati | J7: PLC Rio | K7: NO | L7: Impiantisti | M7: NA | N7: Bassa | O7: Blu | P7: NO | Q7: Nuovo inserimento classe allarme
A8: =CONCATENATE(G8,"-",H8) -> ALR_FAULT_MODULO_2-Allarme fault modulo 2 | B8: =VLOOKUP(A8,'EXPORT IRIS PROD 13-11-2024'!A:A,1,0) -> ALR_FAULT_MODULO_2-Allarme fault modulo 2 | C8: Piemonte | D8: VERTA | E8: SS 229 DEL LAGO D'ORTA | F8: Impianto Rete dati-ANOMALIA | G8: ALR_FAULT_MODULO_2 | H8: Allarme fault modulo 2 | I8: Impianto Rete dati | J8: PLC Rio | K8: NO | L8: Impiantisti | M8: NA | N8: Bassa | O8: Blu | P8: NO | Q8: Nuovo inserimento classe allarme
A9: =CONCATENATE(G9,"-",H9) -> ALR_FAULT_MODULO_3-Allarme fault modulo 3 | B9: =VLOOKUP(A9,'EXPORT IRIS PROD 13-11-2024'!A:A,1,0) -> ALR_FAULT_MODULO_3-Allarme fault modulo 3 | C9: Piemonte | D9: VERTA | E9: SS 229 DEL LAGO D'ORTA | F9: Impianto Rete dati-ANOMALIA | G9: ALR_FAULT_MODULO_3 | H9: Allarme fault modulo 3 | I9: Impianto Rete dati | J9: PLC Rio | K9: NO | L9: Impiantisti | M9: NA | N9: Bassa | O9: Blu | P9: NO | Q9: Nuovo inserimento classe allarme
A10: =CONCATENATE(G10,"-",H10) -> ALR_FAULT_MODULO_4-Allarme fault modulo 4 | B10: =VLOOKUP(A10,'EXPORT IRIS PROD 13-11-2024'!A:A,1,0) -> ALR_FAULT_MODULO_4-Allarme fault modulo 4 | C10: Piemonte | D10: VERTA | E10: SS 229 DEL LAGO D'ORTA | F10: Impianto Rete dati-ANOMALIA | G10: ALR_FAULT_MODULO_4 | H10: Allarme fault modulo 4 | I10: Impianto Rete dati | J10: PLC Rio | K10: NO | L10: Impiantisti | M10: NA | N10: Bassa | O10: Blu | P10: NO | Q10: Nuovo inserimento classe allarme
A11: =CONCATENATE(G11,"-",H11) -> ALR_FAULT_MODULO_5-Allarme fault modulo 5 | B11: =VLOOKUP(A11,'EXPORT IRIS PROD 13-11-2024'!A:A,1,0) -> ALR_FAULT_MODULO_5-Allarme fault modulo 5 | C11: Piemonte | D11: VERTA | E11: SS 229 DEL LAGO D'ORTA | F11: Impianto Rete dati-ANOMALIA | G11: ALR_FAULT_MODULO_5 | H11: Allarme fault modulo 5 | I11: Impianto Rete dati | J11: PLC Rio | K11: NO | L11: Impiantisti | M11: NA | N11: Bassa | O11: Blu | P11: NO | Q11: Nuovo inserimento classe allarme
A12: =CONCATENATE(G12,"-",H12) -> ALR_FAULT_MODULO_6-Allarme fault modulo 6 | B12: =VLOOKUP(A12,'EXPORT IRIS PROD 13-11-2024'!A:A,1,0) -> ALR_FAULT_MODULO_6-Allarme fault modulo 6 | C12: Piemonte | D12: VERTA | E12: SS 229 DEL LAGO D'ORTA | F12: Impianto Rete dati-ANOMALIA | G12: ALR_FAULT_MODULO_6 | H12: Allarme fault modulo 6 | I12: Impianto Rete dati | J12: PLC Rio | K12: NO | L12: Impiantisti | M12: NA | N12: Bassa | O12: Blu | P12: NO | Q12: Nuovo inserimento classe allarme
A13: =CONCATENATE(G13,"-",H13) -> ALR_FAULT_MODULO_7-Allarme fault modulo 7 | B13: =VLOOKUP(A13,'EXPORT IRIS PROD 13-11-2024'!A:A,1,0) -> ALR_FAULT_MODULO_7-Allarme fault modulo 7 | C13: Piemonte | D13: VERTA | E13: SS 229 DEL LAGO D'ORTA | F13: Impianto Rete dati-ANOMALIA | G13: ALR_FAULT_MODULO_7 | H13: Allarme fault modulo 7 | I13: Impianto Rete dati | J13: PLC Rio | K13: NO | L13: Impiantisti | M13: NA | N13: Bassa | O13: Blu | P13: NO | Q13: Nuovo inserimento classe allarme
... A15: =CONCATENATE(G15,"-",H15) -> ALR_FAULT_MODULO_9-Allarme fault modulo 9 | B15: =VLOOKUP(A15,'EXPORT IRIS PROD 13-11-2024'!A:A,1,0) -> ALR_FAULT_MODULO_9-Allarme fault modulo 9 | C15: Piemonte | D15: VERTA | E15: SS 229 DEL LAGO D'ORTA | F15: Impianto Rete dati-ANOMALIA | G15: ALR_FAULT_MODULO_9 | H15: Allarme fault modulo 9 | I15: Impianto Rete dati | J15: PLC Rio | K15: NO | L15: Impiantisti | M15: NA | N15: Bassa | O15: Blu | P15: NO | Q15: Nuovo inserimento classe allarme
A16: =CONCATENATE(G16,"-",H16) -> ALR_CPU-Allarme CPU | B16: =VLOOKUP(A16,'EXPORT IRIS PROD 13-11-2024'!A:A,1,0) -> ALR_CPU-Allarme CPU | C16: Piemonte | D16: VERTA | E16: SS 229 DEL LAGO D'ORTA | F16: Errore PLC | G16: ALR_CPU | H16: Allarme CPU | I16: Impianto Rete dati | J16: PLC | K16: SI | L16: Sala operativa e Impiantisti | M16: 3 | N16: Alta | O16: Rosso | P16: SI | Q16: Nuovo inserimento classe allarme
A17: =CONCATENATE(G17,"-",H17) -> ALR_SEZ_SCATTATO-Allarme sezionatore scattato | B17: =VLOOKUP(A17,'EXPORT IRIS PROD 13-11-2024'!A:A,1,0) -> ALR_SEZ_SCATTATO-Allarme sezionatore scattato | C17: Piemonte | D17: VERTA | E17: SS 229 DEL LAGO D'ORTA | F17: Impianto Elettrico-ANOMALIA | G17: ALR_SEZ_SCATTATO | H17: Allarme sezionatore scattato | I17: Impianto Elettrico | J17: Sezionatore | K17: NO | L17: Impiantisti | M17: NA | N17: Bassa | O17: Blu | P17: NO | Q17: Nuovo inserimento classe allarme
A18: =CONCATENATE(G18,"-",H18) -> ALR-MULTI-FAULT-Allarme multimetro fault | B18: =VLOOKUP(A18,'EXPORT IRIS PROD 13-11-2024'!A:A,1,0) -> ALR-MULTI-FAULT-Allarme multimetro fault | C18: Piemonte | D18: VERTA | E18: SS 229 DEL LAGO D'ORTA | F18: Impianto Elettrico-ANOMALIA | G18: ALR-MULTI-FAULT | H18: Allarme multimetro fault | I18: Impianto Elettrico | J18: Multimetro | K18: NO | L18: Impiantisti | M18: NA | N18: Bassa | O18: Blu | P18: NO | Q18: Nuovo inserimento classe allarme
A19: =CONCATENATE(G19,"-",H19) -> ALR_GENERICO-Allarme dispositivo | B19: =VLOOKUP(A19,'EXPORT IRIS PROD 13-11-2024'!A:A,1,0) -> ALR_GENERICO-Allarme dispositivo | C19: Piemonte | D19: VERTA | E19: SS 229 DEL LAGO D'ORTA | F19: Impianto Elettrico-ANOMALIA | G19: ALR_GENERICO | H19: Allarme dispositivo | I19: Impianto Elettrico | J19: Centralina scambio rete-gruppo | K19: NO | L19: Impiantisti | M19: NA | N19: Bassa | O19: Blu | P19: NO | Q19: Nuova associazione classe-dispositivo
A20: =CONCATENATE(G20,"-",H20) -> CENTRALINA_TRIP_I-Centralina trip | B20: =VLOOKUP(A20,'EXPORT IRIS PROD 13-11-2024'!A:A,1,0) -> CENTRALINA_TRIP_I-Centralina trip | C20: Piemonte | D20: VERTA | E20: SS 229 DEL LAGO D'ORTA | F20: Impianto Elettrico-ANOMALIA | G20: CENTRALINA_TRIP_I | H20: Centralina trip | I20: Impianto elettrico | J20: Centralina scambio rete-gruppo | K20: NO | L20: Impiantisti | M20: NA | N20: Bassa | O20: Blu | P20: NO | Q20: Nuova associazione classe-dispositivo
A21: =CONCATENATE(G21,"-",H21) -> CENTRALINA_TRIP-Centralina trip | B21: =VLOOKUP(A21,'EXPORT IRIS PROD 13-11-2024'!A:A,1,0) -> CENTRALINA_TRIP-Centralina trip | C21: Piemonte | D21: VERTA | E21: SS 229 DEL LAGO D'ORTA | F21: Impianto Elettrico-ANOMALIA | G21: CENTRALINA_TRIP | H21: Centralina trip | I21: Impianto elettrico | J21: Trasformatore | K21: NO | L21: Impiantisti | M21: NA | N21: Bassa | O21: Blu | P21: NO | Q21: Nuova associazione classe-dispositivo
A22: =CONCATENATE(G22,"-",H22) -> CENTRALINA_TRIP_GRUPPO-Centralina trip Gruppo | B22: =VLOOKUP(A22,'EXPORT IRIS PROD 13-11-2024'!A:A,1,0) -> CENTRALINA_TRIP_GRUPPO-Centralina trip Gruppo | C22: Piemonte | D22: VERTA | E22: SS 229 DEL LAGO D'ORTA | F22: Impianto Elettrico-ANOMALIA | G22: CENTRALINA_TRIP_GRUPPO | H22: Centralina trip Gruppo | I22: Impianto elettrico | J22: Centralina scambio rete-gruppo | K22: NO | L22: Impiantisti | M22: NA | N22: Bassa | O22: Blu | P22: NO | Q22: Nuovo inserimento classe allarme
A23: =CONCATENATE(G23,"-",H23) -> ALR_GUASTO_2_IMP-Allarme guasto dispositivo | B23: =VLOOKUP(A23,'EXPORT IRIS PROD 13-11-2024'!A:A,1,0) -> ALR_GUASTO_2_IMP-Allarme guasto dispositivo | C23: Piemonte | D23: VERTA | E23: SS 229 DEL LAGO D'ORTA | F23: Impianto Elettrico-ANOMALIA | G23: ALR_GUASTO_2_IMP | H23: Allarme guasto dispositivo | I23: Impianto Elettrico | J23: Centrale antintrusione | K23: NO | L23: Impiantisti | M23: NA | N23: Bassa | O23: Blu | P23: NO | Q23: Nuova associazione classe-dispositivo
A24: =CONCATENATE(G24,"-",H24) -> ALR_NON_PRONTO-Allarme dispositivo non pronto | B24: =VLOOKUP(A24,'EXPORT IRIS PROD 13-11-2024'!A:A,1,0) -> ALR_NON_PRONTO-Allarme dispositivo non pronto | C24: Piemonte | D24: VERTA | E24: SS 229 DEL LAGO D'ORTA | F24: Errore PLC | G24: ALR_NON_PRONTO | H24: Allarme dispositivo non pronto | I24: Impianto Rete dati | J24: PLC | K24: SI | L24: Sala operativa e Impiantisti | M24: 3 | N24: Alta | O24: Rosso | P24: SI | Q24: Nuova associazione classe-dispositivo
A25: =CONCATENATE(G25,"-",H25) -> ALR_COMUNICAZIONE_2_IMP-Allarme comunicazione dispositivo | B25: =VLOOKUP(A25,'EXPORT IRIS PROD 13-11-2024'!A:A,1,0) -> ALR_COMUNICAZIONE_2_IMP-Allarme comunicazione dispositivo | C25: Piemonte | D25: VERTA | E25: SS 229 DEL LAGO D'ORTA | F25: Impianto Elettrico-ANOMALIA | G25: ALR_COMUNICAZIONE_2_IMP | H25: Allarme comunicazione dispositivo | I25: Impianto Elettrico | J25: Centralina scambio rete-gruppo | K25: NO | L25: Impiantisti | M25: NA | N25: Bassa | O25: Blu | P25: NO | Q25: Nuova associazione classe-dispositivo
A26: =CONCATENATE(G26,"-",H26) -> ALR_SURRISCALDAMENTO-Allarme surriscaldamento | B26: =VLOOKUP(A26,'EXPORT IRIS PROD 13-11-2024'!A:A,1,0) -> ALR_SURRISCALDAMENTO-Allarme surriscaldamento | C26: A2 | D26: SERRA SPIGA | E26: A2 | F26: Videosorveglianza-ANOMALIA | G26: ALR_SURRISCALDAMENTO | H26: Allarme surriscaldamento | I26: Impianto videosorveglianza | J26: Telecamera | K26: NO | L26: Impiantisti | M26: NA | N26: Bassa | O26: Blu | P26: NO | Q26: Nuovo inserimento classe allarme
A27: =CONCATENATE(G27,"-",H27) -> ALR_FAULT_CORSIA_3-Allarme fault corsia veloce | B27: =VLOOKUP(A27,'EXPORT IRIS PROD 13-11-2024'!A:A,1,0) -> ALR_FAULT_CORSIA_3-Allarme fault corsia veloce | C27: A2 | D27: SERRA SPIGA | E27: A2 | F27: Videosorveglianza-ANOMALIA | G27: ALR_FAULT_CORSIA_3 | H27: Allarme fault corsia veloce | I27: Impianto videosorveglianza | J27: Telecamera | K27: NO | L27: Impiantisti | M27: NA | N27: Bassa | O27: Blu | P27: NO | Q27: Nuovo inserimento classe allarme
A28: =CONCATENATE(G28,"-",H28) -> ALR_FAULT_CORSIA_1-Allarme fault corsia di emergenza | B28: =VLOOKUP(A28,'EXPORT IRIS PROD 13-11-2024'!A:A,1,0) -> ALR_FAULT_CORSIA_1-Allarme fault corsia di emergenza | C28: A2 | D28: SERRA SPIGA | E28: A2 | F28: Videosorveglianza-ANOMALIA | G28: ALR_FAULT_CORSIA_1 | H28: Allarme fault corsia di emergenza | I28: Impianto videosorveglianza | J28: Telecamera | K28: NO | L28: Impiantisti | M28: NA | N28: Bassa | O28: Blu | P28: NO | Q28: Nuovo inserimento classe allarme
A29: =CONCATENATE(G29,"-",H29) -> ALR_FAULT_CORSIA_2-Allarme fault corsia di marcia | B29: =VLOOKUP(A29,'EXPORT IRIS PROD 13-11-2024'!A:A,1,0) -> ALR_FAULT_CORSIA_2-Allarme fault corsia di marcia | C29: A2 | D29: SERRA SPIGA | E29: A2 | F29: Videosorveglianza-ANOMALIA | G29: ALR_FAULT_CORSIA_2 | H29: Allarme fault corsia di marcia | I29: Impianto videosorveglianza | J29: Telecamera | K29: NO | L29: Impiantisti | M29: NA | N29: Bassa | O29: Blu | P29: NO | Q29: Nuovo inserimento classe allarme
A30: =CONCATENATE(G30,"-",H30) -> ALR_KO_CORSIA_1-Allarme non attiva corsia di emergenza | B30: =VLOOKUP(A30,'EXPORT IRIS PROD 13-11-2024'!A:A,1,0) -> ALR_KO_CORSIA_1-Allarme non attiva corsia di emergenza | C30: A2 | D30: SERRA SPIGA | E30: A2 | F30: Videosorveglianza-ANOMALIA | G30: ALR_KO_CORSIA_1 | H30: Allarme non attiva corsia di emergenza | I30: Impianto videosorveglianza | J30: Telecamera | K30: NO | L30: Impiantisti | M30: NA | N30: Bassa | O30: Blu | P30: NO | Q30: Nuovo inserimento classe allarme
A31: =CONCATENATE(G31,"-",H31) -> ALR_KO_CORSIA_2-Allarme non attiva corsia di marcia | B31: =VLOOKUP(A31,'EXPORT IRIS PROD 13-11-2024'!A:A,1,0) -> ALR_KO_CORSIA_2-Allarme non attiva corsia di marcia | C31: A2 | D31: SERRA SPIGA | E31: A2 | F31: Videosorveglianza-ANOMALIA | G31: ALR_KO_CORSIA_2 | H31: Allarme non attiva corsia di marcia | I31: Impianto videosorveglianza | J31: Telecamera | K31: NO | L31: Impiantisti | M31: NA | N31: Bassa | O31: Blu | P31: NO | Q31: Nuovo inserimento classe allarme
A32: =CONCATENATE(G32,"-",H32) -> ALR_KO_CORSIA_3-Allarme non attiva corsia veloce | B32: =VLOOKUP(A32,'EXPORT IRIS PROD 13-11-2024'!A:A,1,0) -> ALR_KO_CORSIA_3-Allarme non attiva corsia veloce | C32: A2 | D32: SERRA SPIGA | E32: A2 | F32: Videosorveglianza-ANOMALIA | G32: ALR_KO_CORSIA_3 | H32: Allarme non attiva corsia veloce | I32: Impianto videosorveglianza | J32: Telecamera | K32: NO | L32: Impiantisti | M32: NA | N32: Bassa | O32: Blu | P32: NO | Q32: Nuovo inserimento classe allarme
A33: =CONCATENATE(G33,"-",H33) -> ALR-SLOT-1-Allarme Slot 1 | B33: =VLOOKUP(A33,'EXPORT IRIS PROD 13-11-2024'!A:A,1,0) -> ALR-SLOT-1-Allarme Slot 1 | C33: A2 | D33: SERRA SPIGA | E33: A2 | F33: Impianto Rete dati-ANOMALIA | G33: ALR-SLOT-1 | H33: Allarme Slot 1 | I33: Impianto Rete dati | J33: PLC Rio | K33: NO | L33: Impiantisti | M33: NA | N33: Bassa | O33: Blu | P33: NO | Q33: Nuovo inserimento classe allarme
A34: =CONCATENATE(G34,"-",H34) -> ALR-SLOT-2-Allarme Slot 2 | B34: =VLOOKUP(A34,'EXPORT IRIS PROD 13-11-2024'!A:A,1,0) -> ALR-SLOT-2-Allarme Slot 2 | C34: A2 | D34: SERRA SPIGA | E34: A2 | F34: Impianto Rete dati-ANOMALIA | G34: ALR-SLOT-2 | H34: Allarme Slot 2 | I34: Impianto Rete dati | J34: PLC Rio | K34: NO | L34: Impiantisti | M34: NA | N34: Bassa | O34: Blu | P34: NO | Q34: Nuovo inserimento classe allarme
A35: =CONCATENATE(G35,"-",H35) -> ALR-SLOT-3-Allarme Slot 3 | B35: =VLOOKUP(A35,'EXPORT IRIS PROD 13-11-2024'!A:A,1,0) -> ALR-SLOT-3-Allarme Slot 3 | C35: A2 | D35: SERRA SPIGA | E35: A2 | F35: Impianto Rete dati-ANOMALIA | G35: ALR-SLOT-3 | H35: Allarme Slot 3 | I35: Impianto Rete dati | J35: PLC Rio | K35: NO | L35: Impiantisti | M35: NA | N35: Bassa | O35: Blu | P35: NO | Q35: Nuovo inserimento classe allarme
A36: =CONCATENATE(G36,"-",H36) -> ALR_COMUNICAZIONE_MODULO-Allarme comunicazione modulo | B36: =VLOOKUP(A36,'EXPORT IRIS PROD 13-11-2024'!A:A,1,0) -> ALR_COMUNICAZIONE_MODULO-Allarme comunicazione modulo | C36: A2 | D36: SERRA SPIGA | E36: A2 | F36: Impianto Rete dati-ANOMALIA | G36: ALR_COMUNICAZIONE_MODULO | H36: Allarme comunicazione modulo | I36: Impianto Rete dati | J36: PLC Rio | K36: NO | L36: Impiantisti | M36: NA | N36: Bassa | O36: Blu | P36: NO | Q36: Nuovo inserimento classe allarme
A37: =CONCATENATE(G37,"-",H37) -> INCENDIO_IN_GALLERIA_DA_TLC_NORD-Allarme incendio in galleria da TLC Nord | B37: =VLOOKUP(A37,'EXPORT IRIS PROD 13-11-2024'!A:A,1,0) -> INCENDIO_IN_GALLERIA_DA_TLC_NORD-Allarme incendio in galleria da TLC Nord | C37: A2 | D37: SERRA SPIGA | E37: A2 | F37: Incendio | G37: INCENDIO_IN_GALLERIA_DA_TLC_NORD | H37: Allarme incendio in galleria da TLC Nord | I37: Impianto Rilevazione Incendio | J37: Centralina rilevazione incendio/fibrolaser | K37: SI | L37: Sala operativa e Impiantisti | M37: 2 | N37: Altissima | O37: Viola | P37: SI | Q37: Nuovo inserimento classe allarme
A38: =CONCATENATE(G38,"-",H38) -> INCENDIO_IN_GALLERIA_DA_TLC_SUD-Allarme incendio in galleria da TLC Sud | B38: =VLOOKUP(A38,'EXPORT IRIS PROD 13-11-2024'!A:A,1,0) -> INCENDIO_IN_GALLERIA_DA_TLC_SUD-Allarme incendio in galleria da TLC Sud | C38: A2 | D38: SERRA SPIGA | E38: A2 | F38: Incendio | G38: INCENDIO_IN_GALLERIA_DA_TLC_SUD | H38: Allarme incendio in galleria da TLC Sud | I38: Impianto Rilevazione Incendio | J38: Centralina rilevazione incendio/fibrolaser | K38: SI | L38: Sala operativa e Impiantisti | M38: 2 | N38: Altissima | O38: Viola | P38: SI | Q38: Nuovo inserimento classe allarme
A39: =CONCATENATE(G39,"-",H39) -> ALR_COMUNICAZIONE_PORTA_1-Allarme comunicazione porta 1 | B39: =VLOOKUP(A39,'EXPORT IRIS PROD 13-11-2024'!A:A,1,0) -> ALR_COMUNICAZIONE_PORTA_1-Allarme comunicazione porta 1 | C39: Lazio | D39: SANT'ANGELO E SAN QUIRICO | E39: SS4 | F39: Impianto Rete dati-ANOMALIA | G39: ALR_COMUNICAZIONE_PORTA_1 | H39: Allarme comunicazione porta 1 | I39: Impianto rete dati | J39: PLC primario/di cabina | K39: NO | L39: Impiantisti | M39: NA | N39: Bassa | O39: {=_xlfn.IFS(N39="Bassa", "Blu", N39="Media", "Arancione", N39="Alta", "Rosso", N39="Altissima", "Viola")} -> Blu | P39: NO | Q39: Nuovo inserimento classe allarme
A40: =CONCATENATE(G40,"-",H40) -> ALR_COMUNICAZIONE_PORTA_2-Allarme comunicazione porta 2 | B40: =VLOOKUP(A40,'EXPORT IRIS PROD 13-11-2024'!A:A,1,0) -> ALR_COMUNICAZIONE_PORTA_2-Allarme comunicazione porta 2 | C40: Lazio | D40: SANT'ANGELO E SAN QUIRICO | E40: SS4 | F40: Impianto Rete dati-ANOMALIA | G40: ALR_COMUNICAZIONE_PORTA_2 | H40: Allarme comunicazione porta 2 | I40: Impianto rete dati | J40: PLC primario/di cabina | K40: NO | L40: Impiantisti | M40: NA | N40: Bassa | O40: {=_xlfn.IFS(N40="Bassa", "Blu", N40="Media", "Arancione", N40="Alta", "Rosso", N40="Altissima", "Viola")} -> Blu | P40: NO | Q40: Nuovo inserimento classe allarme
A41: =CONCATENATE(G41,"-",H41) -> ALR_COMUNICAZIONE_PORTA_3-Allarme comunicazione porta 3 | B41: =VLOOKUP(A41,'EXPORT IRIS PROD 13-11-2024'!A:A,1,0) -> ALR_COMUNICAZIONE_PORTA_3-Allarme comunicazione porta 3 | C41: Lazio | D41: SANT'ANGELO E SAN QUIRICO | E41: SS4 | F41: Impianto Rete dati-ANOMALIA | G41: ALR_COMUNICAZIONE_PORTA_3 | H41: Allarme comunicazione porta 3 | I41: Impianto rete dati | J41: PLC primario/di cabina | K41: NO | L41: Impiantisti | M41: NA | N41: Bassa | O41: {=_xlfn.IFS(N41="Bassa", "Blu", N41="Media", "Arancione", N41="Alta", "Rosso", N41="Altissima", "Viola")} -> Blu | P41: NO | Q41: Nuovo inserimento classe allarme
...

Sheet Categorie Allarmi
A1: MACRO CATEGORIE | B1: CATEGORIE | C1: DESCRIZIONE CATEGORIE
A2: FUNZIONAMENTO | B2: Allagamento | C2: Rilevazione di Allagamento attraverso l'attivazione di sonde e sensori che hanno generato l'attivazione dell'allarme
B3: Antincendio | C3: Rilevazione dell'avvio dell'Antincendio attraverso l'attivazione di pompe varie che hanno generato l'attivazione dell'allarme
B4: Bypass | C4: Rilevazione dell'avvio di uno o più componenti del bypass che hanno generato l'allarme
B5: Bypass-Apertura Porte o Serrande | C5: Rilevazione di apertura di porte/serrande di Bypass che hanno generato l'attivazione dell'allarme
B6: Cabina Elettrica-Intrusione | C6: Rilevazione attraverso vari dispositivi dell'itrusione/manomissione in Cabina Elettrica che ha generato l'attivazione dell'allarme
B7: Cambio Corsia | C7: Rilevazione di Cambio Corsia attraverso analisi video che ha generato l'attivazione dell'allarme
B8: Canalizzazione | C8: Rilevazione dell'attivazione del Rotocarrello in caso di incidente che ha generato l'attivazione dell'allarme
B9: Coda | C9: Rilevazione di Coda attraverso analisi video che ha generato l'attivazione dell'allarme
B10: Errore PLC | C10: Rilevazione di errori logici del PLC dell'Impianto Rete dati che ha generato l'attivazione dell'allarme
B11: Fumo | C11: Rilevazione di Fumo attraverso analisi video che ha generato l'attivazione dell'allarme
B12: Gruppo elettrogeno avviato | C12: Rilevazione dell'avvio del Gruppo elettrogeno dell'impianto elettrico che ha generato l'attivazione dell'allarme
B13: Idrometrico | C13: Rilevazione del superamento soglie Idrometriche attraverso l'attivazione di sensori che ha generato l'attivazione dell'allarme
B14: Impianto Radio | C14: Rilevazione dell'attivazione del microfono dell'impianto radio che ha generato l'attivazione dell'allarme
... B30: Ventilazione | C30: Rilevazione di attivazione di processi di funzionamento dell'mpianto di ventilazione (Es. lavaggio) che hanno generato l'attivazione di allarmi
A31: ANOMALIE TECNICHE / MALFUNZIONAMENTI | B31: Allagamento-ANOMALIA | C31: Anomalia tecnica/malfunzionamento di uno o più componenti dell'impianto di Allagamento
B32: Antincendio-ANOMALIA | C32: Anomalia tecnica/malfunzionamento di uno o più componenti dell'impianto Antincendio
B33: Bypass-ANOMALIA | C33: Anomalia tecnica/malfunzionamento di uno o più componenti dell'impianto Bypass
B34: Cabina Elettrica-ANOMALIA | C34: Anomalia tecnica/malfunzionamento di uno o più componenti dell'impianto Cabina Elettrica
B35: Canalizzazione-ANOMALIA | C35: Anomalia tecnica/malfunzionamento di uno o più componenti dell'impianto Canalizzazione
B36: Cantieri IoT-ANOMALIA | C36: Anomalia tecnica/malfunzionamento di uno o più componenti dell'impianto Cantieri IoT
B37: GI-Elettrico-ANOMALIA | C37: Anomalia tecnica/malfunzionamento di uno o più componenti dell'impianto Elettrico delle GI
B38: Illuminazione-ANOMALIA | C38: Anomalia tecnica/malfunzionamento di uno o più componenti dell'impianto di Illuminazione
B39: Impianto Elettrico-ANOMALIA | C39: Anomalia tecnica/malfunzionamento di uno o più componenti dell'impianto Elettrico
B40: Impianto Radio-ANOMALIA | C40: Anomalia tecnica/malfunzionamento di uno o più componenti dell'impianto Radio
B41: Impianto Rete dati-ANOMALIA | C41: Anomalia tecnica/malfunzionamento di uno o più componenti dell'impianto Rete Dati
B42: Impianto Rilevazione Incendio-ANOMALIA | C42: Anomalia tecnica/malfunzionamento di uno o più componenti dell'impianto Rilevazione Incendio
B43: Impianto SOS-ANOMALIA | C43: Anomalia tecnica/malfunzionamento di uno o più componenti dell'impianto SOS
... B47: Videosorveglianza-ANOMALIA | C47: Anomalia tecnica/malfunzionamento di uno o più componenti dell'impianto Videosorveglianza

Sheet RIFERIMENTO
A1: dispo+nome+descrizione | B1: nome+descrizione | C1: check con rev4 | D1: CHECK nome+descrizione | E1: check nome | F1: check descriz. | G1: CATEGORIA ALLARME | H1: CODICE ALLARME | I1: DESCRIZIONE ALLARME | J1: IMPIANTO | K1: DISPOSITIVO | L1: PRESENTE IN PROCEDURA | M1: CHI VISUALIZZA L'ALLARME | N1: ID ISTRUZIONE OPERATIVA ALLARMI | O1: PRIORITÀ ALLARME | P1: COLORE NOTIFICA ALLARME | Q1: ALLARME SONORO RMT | R1: NOTE
A2: =CONCATENATE(J2,"_",K2,"_",B2) -> Impianto Rete dati_Rack radio_ALL_PLC_RACK-Allarme plc rack | B2: =CONCATENATE(H2,"-",I2) -> ALL_PLC_RACK-Allarme plc rack | C2: =VLOOKUP(B2,'[2]Classi allarmi RMT-STIG_rev4'!$C:$C,1,0) -> ALL_PLC_RACK-Allarme plc rack | D2: =VLOOKUP(B2,'EXPORT IRIS PROD 13-11-2024'!A:A,1,0) -> ALL_PLC_RACK-Allarme plc rack | E2: =VLOOKUP(H2,'EXPORT IRIS PROD 13-11-2024'!F:F,1,0) -> ALL_PLC_RACK | F2: =VLOOKUP(I2,'EXPORT IRIS PROD 13-11-2024'!D:D,1,0) -> Allarme plc rack | G2: Impianto Rete dati-ANOMALIA | H2: ALL_PLC_RACK | I2: Allarme plc rack | J2: Impianto Rete dati | K2: Rack radio | L2: NO | M2: Impiantisti | N2: NA | O2: Bassa | P2: Blu | Q2: NO
A3: =CONCATENATE(J3,"_",K3,"_",B3) -> Impianto SOS_Colonnina Sos_ALLARME_DA_SOS-Allarme SOS premuto | B3: =CONCATENATE(H3,"-",I3) -> ALLARME_DA_SOS-Allarme SOS premuto | C3: =VLOOKUP(B3,'[2]Classi allarmi RMT-STIG_rev4'!$C:$C,1,0) -> ALLARME_DA_SOS-Allarme SOS premuto | D3: =VLOOKUP(B3,'EXPORT IRIS PROD 13-11-2024'!A:A,1,0) -> ALLARME_DA_SOS-Allarme SOS premuto | E3: =VLOOKUP(H3,'EXPORT IRIS PROD 13-11-2024'!F:F,1,0) -> ALLARME_DA_SOS | F3: =VLOOKUP(I3,'EXPORT IRIS PROD 13-11-2024'!D:D,1,0) -> Allarme SOS premuto | G3: Soccorso SOS | H3: ALLARME_DA_SOS | I3: Allarme SOS premuto | J3: Impianto SOS | K3: Colonnina Sos | L3: SI | M3: Sala operativa e Impiantisti | N3: 1 | O3: Alta | P3: Rosso | Q3: SI
A4: =CONCATENATE(J4,"_",K4,"_",B4) -> Impianto Antincendio_Pompa_ALLARME_GENERICO-allarme generico | B4: =CONCATENATE(H4,"-",I4) -> ALLARME_GENERICO-allarme generico | C4: =VLOOKUP(B4,'[2]Classi allarmi RMT-STIG_rev4'!$C:$C,1,0) -> ALLARME_GENERICO-allarme generico | D4: =VLOOKUP(B4,'EXPORT IRIS PROD 13-11-2024'!A:A,1,0) -> ALLARME_GENERICO-allarme generico | E4: =VLOOKUP(H4,'EXPORT IRIS PROD 13-11-2024'!F:F,1,0) -> ALLARME_GENERICO | F4: =VLOOKUP(I4,'EXPORT IRIS PROD 13-11-2024'!D:D,1,0) -> allarme generico | G4: Antincendio-ANOMALIA | H4: ALLARME_GENERICO | I4: allarme generico | J4: Impianto Antincendio | K4: Pompa | L4: NO | M4: Impiantisti | N4: NA | O4: Bassa | P4: Blu | Q4: NO
A5: =CONCATENATE(J5,"_",K5,"_",B5) -> Impianto Rilevazione Incendio_Centralina rilevazione incendio in cabina_ALLARME_INCENDIO_CABINA-Allarme incendio in cabina | B5: =CONCATENATE(H5,"-",I5) -> ALLARME_INCENDIO_CABINA-Allarme incendio in cabina | C5: =VLOOKUP(B5,'[2]Classi allarmi RMT-STIG_rev4'!$C:$C,1,0) -> ALLARME_INCENDIO_CABINA-Allarme incendio in cabina | D5: =VLOOKUP(B5,'EXPORT IRIS PROD 13-11-2024'!A:A,1,0) -> ALLARME_INCENDIO_CABINA-Allarme incendio in cabina | E5: =VLOOKUP(H5,'EXPORT IRIS PROD 13-11-2024'!F:F,1,0) -> ALLARME_INCENDIO_CABINA | F5: =VLOOKUP(I5,'EXPORT IRIS PROD 13-11-2024'!D:D,1,0) -> Allarme incendio in cabina | G5: Incendio | H5: ALLARME_INCENDIO_CABINA | I5: Allarme incendio in cabina | J5: Impianto Rilevazione Incendio | K5: Centralina rilevazione incendio in cabina | L5: SI | M5: Sala operativa e Impiantisti | N5: 2 | O5: Altissima | P5: Viola | Q5: SI
A6: =CONCATENATE(J6,"_",K6,"_",B6) -> Impianto Ventilazione_CO_ALLARME_INCENDIO_DA_SENSORE-Allarme incendio da sensori | B6: =CONCATENATE(H6,"-",I6) -> ALLARME_INCENDIO_DA_SENSORE-Allarme incendio da sensori | C6: =VLOOKUP(B6,'[2]Classi allarmi RMT-STIG_rev4'!$C:$C,1,0) -> ALLARME_INCENDIO_DA_SENSORE-Allarme incendio da sensori | D6: =VLOOKUP(B6,'EXPORT IRIS PROD 13-11-2024'!A:A,1,0) -> ALLARME_INCENDIO_DA_SENSORE-Allarme incendio da sensori | E6: =VLOOKUP(H6,'EXPORT IRIS PROD 13-11-2024'!F:F,1,0) -> ALLARME_INCENDIO_DA_SENSORE | F6: =VLOOKUP(I6,'EXPORT IRIS PROD 13-11-2024'!D:D,1,0) -> Allarme incendio da sensori | G6: Pre Allarme Incendio | H6: ALLARME_INCENDIO_DA_SENSORE | I6: Allarme incendio da sensori | J6: Impianto Ventilazione | K6: CO | L6: SI | M6: Sala operativa e Impiantisti | N6: 2 | O6: Altissima | P6: Viola | Q6: SI
A7: =CONCATENATE(J7,"_",K7,"_",B7) -> Impianto Ventilazione_OP_ALLARME_INCENDIO_DA_SENSORE-Allarme incendio da sensori | B7: =CONCATENATE(H7,"-",I7) -> ALLARME_INCENDIO_DA_SENSORE-Allarme incendio da sensori | C7: =VLOOKUP(B7,'[2]Classi allarmi RMT-STIG_rev4'!$C:$C,1,0) -> ALLARME_INCENDIO_DA_SENSORE-Allarme incendio da sensori | D7: =VLOOKUP(B7,'EXPORT IRIS PROD 13-11-2024'!A:A,1,0) -> ALLARME_INCENDIO_DA_SENSORE-Allarme incendio da sensori | E7: =VLOOKUP(H7,'EXPORT IRIS PROD 13-11-2024'!F:F,1,0) -> ALLARME_INCENDIO_DA_SENSORE | F7: =VLOOKUP(I7,'EXPORT IRIS PROD 13-11-2024'!D:D,1,0) -> Allarme incendio da sensori | G7: Pre Allarme Incendio | H7: ALLARME_INCENDIO_DA_SENSORE | I7: Allarme incendio da sensori | J7: Impianto Ventilazione | K7: OP | L7: SI | M7: Sala operativa e Impiantisti | N7: 2 | O7: Altissima | P7: Viola | Q7: SI
A8: =CONCATENATE(J8,"_",K8,"_",B8) -> Impianto Elettrico_Gruppo elettrogeno_ALR_1_GRUPPO_ELETTROGENO-Allarme centralina gestione elettronica GE - alarm1 | B8: =CONCATENATE(H8,"-",I8) -> ALR_1_GRUPPO_ELETTROGENO-Allarme centralina gestione elettronica GE - alarm1 | C8: =VLOOKUP(B8,'[2]Classi allarmi RMT-STIG_rev4'!$C:$C,1,0) -> ALR_1_GRUPPO_ELETTROGENO-Allarme centralina gestione elettronica GE - alarm1 | D8: =VLOOKUP(B8,'EXPORT IRIS PROD 13-11-2024'!A:A,1,0) -> ALR_1_GRUPPO_ELETTROGENO-Allarme centralina gestione elettronica GE - alarm1 | E8: =VLOOKUP(H8,'EXPORT IRIS PROD 13-11-2024'!F:F,1,0) -> ALR_1_GRUPPO_ELETTROGENO | F8: =VLOOKUP(I8,'EXPORT IRIS PROD 13-11-2024'!D:D,1,0) -> Allarme centralina gestione elettronica GE - alarm1 | G8: Impianto Elettrico-ANOMALIA | H8: ALR_1_GRUPPO_ELETTROGENO | I8: Allarme centralina gestione elettronica GE - alarm1 | J8: Impianto Elettrico | K8: Gruppo elettrogeno | L8: NO | M8: Impiantisti | N8: NA | O8: Bassa | P8: Blu | Q8: NO
A9: =CONCATENATE(J9,"_",K9,"_",B9) -> Impianto SOS_Colonnina Sos_ALR_113-Allarme SOS pulsante 113 | B9: =CONCATENATE(H9,"-",I9) -> ALR_113-Allarme SOS pulsante 113 | C9: =VLOOKUP(B9,'[2]Classi allarmi RMT-STIG_rev4'!$C:$C,1,0) -> ALR_113-Allarme SOS pulsante 113 | D9: =VLOOKUP(B9,'EXPORT IRIS PROD 13-11-2024'!A:A,1,0) -> ALR_113-Allarme SOS pulsante 113 | E9: =VLOOKUP(H9,'EXPORT IRIS PROD 13-11-2024'!F:F,1,0) -> ALR_113 | F9: =VLOOKUP(I9,'EXPORT IRIS PROD 13-11-2024'!D:D,1,0) -> Allarme SOS pulsante 113 | G9: Soccorso SOS | H9: ALR_113 | I9: Allarme SOS pulsante 113 | J9: Impianto SOS | K9: Colonnina Sos | L9: SI | M9: Sala operativa e Impiantisti | N9: 1 | O9: Alta | P9: Rosso | Q9: SI
A10: =CONCATENATE(J10,"_",K10,"_",B10) -> Impianto SOS_Colonnina Sos_ALR_115-Allarme SOS pulsante 115 | B10: =CONCATENATE(H10,"-",I10) -> ALR_115-Allarme SOS pulsante 115 | C10: =VLOOKUP(B10,'[2]Classi allarmi RMT-STIG_rev4'!$C:$C,1,0) -> ALR_115-Allarme SOS pulsante 115 | D10: =VLOOKUP(B10,'EXPORT IRIS PROD 13-11-2024'!A:A,1,0) -> ALR_115-Allarme SOS pulsante 115 | E10: =VLOOKUP(H10,'EXPORT IRIS PROD 13-11-2024'!F:F,1,0) -> ALR_115 | F10: =VLOOKUP(I10,'EXPORT IRIS PROD 13-11-2024'!D:D,1,0) -> Allarme SOS pulsante 115 | G10: Soccorso SOS | H10: ALR_115 | I10: Allarme SOS pulsante 115 | J10: Impianto SOS | K10: Colonnina Sos | L10: SI | M10: Sala operativa e Impiantisti | N10: 1 | O10: Alta | P10: Rosso | Q10: SI
A11: =CONCATENATE(J11,"_",K11,"_",B11) -> Impianto SOS_Colonnina Sos_ALR_118-Allarme SOS pulsante 118 | B11: =CONCATENATE(H11,"-",I11) -> ALR_118-Allarme SOS pulsante 118 | C11: =VLOOKUP(B11,'[2]Classi allarmi RMT-STIG_rev4'!$C:$C,1,0) -> ALR_118-Allarme SOS pulsante 118 | D11: =VLOOKUP(B11,'EXPORT IRIS PROD 13-11-2024'!A:A,1,0) -> ALR_118-Allarme SOS pulsante 118 | E11: =VLOOKUP(H11,'EXPORT IRIS PROD 13-11-2024'!F:F,1,0) -> ALR_118 | F11: =VLOOKUP(I11,'EXPORT IRIS PROD 13-11-2024'!D:D,1,0) -> Allarme SOS pulsante 118 | G11: Soccorso SOS | H11: ALR_118 | I11: Allarme SOS pulsante 118 | J11: Impianto SOS | K11: Colonnina Sos | L11: SI | M11: Sala operativa e Impiantisti | N11: 1 | O11: Alta | P11: Rosso | Q11: SI
A12: =CONCATENATE(J12,"_",K12,"_",B12) -> Impianto Elettrico_Gruppo elettrogeno_ALR_2_GRUPPO_ELETTROGENO-Allarme centralina gestione elettronica GE - alarm2 | B12: =CONCATENATE(H12,"-",I12) -> ALR_2_GRUPPO_ELETTROGENO-Allarme centralina gestione elettronica GE - alarm2 | C12: =VLOOKUP(B12,'[2]Classi allarmi RMT-STIG_rev4'!$C:$C,1,0) -> ALR_2_GRUPPO_ELETTROGENO-Allarme centralina gestione elettronica GE - alarm2 | D12: =VLOOKUP(B12,'EXPORT IRIS PROD 13-11-2024'!A:A,1,0) -> ALR_2_GRUPPO_ELETTROGENO-Allarme centralina gestione elettronica GE - alarm2 | E12: =VLOOKUP(H12,'EXPORT IRIS PROD 13-11-2024'!F:F,1,0) -> ALR_2_GRUPPO_ELETTROGENO | F12: =VLOOKUP(I12,'EXPORT IRIS PROD 13-11-2024'!D:D,1,0) -> Allarme centralina gestione elettronica GE - alarm2 | G12: Impianto Elettrico-ANOMALIA | H12: ALR_2_GRUPPO_ELETTROGENO | I12: Allarme centralina gestione elettronica GE - alarm2 | J12: Impianto Elettrico | K12: Gruppo elettrogeno | L12: NO | M12: Impiantisti | N12: NA | O12: Bassa | P12: Blu | Q12: NO
A13: =CONCATENATE(J13,"_",K13,"_",B13) -> Impianto SOS_Colonnina Sos_ALR_800116-Allarme SOS soccorso meccanico_800116 | B13: =CONCATENATE(H13,"-",I13) -> ALR_800116-Allarme SOS soccorso meccanico_800116 | C13: =VLOOKUP(B13,'[2]Classi allarmi RMT-STIG_rev4'!$C:$C,1,0) -> ALR_800116-Allarme SOS soccorso meccanico_800116 | D13: =VLOOKUP(B13,'EXPORT IRIS PROD 13-11-2024'!A:A,1,0) -> ALR_800116-Allarme SOS soccorso meccanico_800116 | E13: =VLOOKUP(H13,'EXPORT IRIS PROD 13-11-2024'!F:F,1,0) -> ALR_800116 | F13: =VLOOKUP(I13,'EXPORT IRIS PROD 13-11-2024'!D:D,1,0) -> Allarme SOS soccorso meccanico_800116 | G13: Soccorso SOS | H13: ALR_800116 | I13: Allarme SOS soccorso meccanico_800116 | J13: Impianto SOS | K13: Colonnina Sos | L13: SI | M13: Sala operativa e Impiantisti | N13: 1 | O13: Alta | P13: Rosso | Q13: SI
A14: =CONCATENATE(J14,"_",K14,"_",B14) -> Impianto SOS_Colonnina Sos_ALR_803116-Allarme SOS soccorso meccanico_803116 | B14: =CONCATENATE(H14,"-",I14) -> ALR_803116-Allarme SOS soccorso meccanico_803116 | C14: =VLOOKUP(B14,'[2]Classi allarmi RMT-STIG_rev4'!$C:$C,1,0) -> ALR_803116-Allarme SOS soccorso meccanico_803116 | D14: =VLOOKUP(B14,'EXPORT IRIS PROD 13-11-2024'!A:A,1,0) -> ALR_803116-Allarme SOS soccorso meccanico_803116 | E14: =VLOOKUP(H14,'EXPORT IRIS PROD 13-11-2024'!F:F,1,0) -> ALR_803116 | F14: =VLOOKUP(I14,'EXPORT IRIS PROD 13-11-2024'!D:D,1,0) -> Allarme SOS soccorso meccanico_803116 | G14: Soccorso SOS | H14: ALR_803116 | I14: Allarme SOS soccorso meccanico_803116 | J14: Impianto SOS | K14: Colonnina Sos | L14: SI | M14: Sala operativa e Impiantisti | N14: 1 | O14: Alta | P14: Rosso | Q14: SI
