Workbook

Sheet WIP
A1: RIFERIMENTO PLC | B1: NOME CABINA | C1: QUADRO | D1: DISPOSITIVO | E1: NOME SPECIFICO /NUMERAZIONE | F1: TIPO REGISTRO | G1: TIPO TAG | H1: TIPO VALORE | I1: INDIRIZZO MODBUS | J1: DESCRIZIONE | K1: rawAddress | L1: rawBitIndex | M1: rawRegister | N1: rawRegisterType | O1: rawDataType | P1: rawDispositivo | Q1: rawSegnale | R1: rawDescrizione | S1: rawDescr&Signal | T1: rawLogica | U1: rawTags | V1: rawQuadro | W1: rawCabina | X1: rawDirezione | Y1: rawReference | Z1: rawIpPlc | AA1: NewRegisterType | AB1: NewDataValueType | AC1: NewTag | AD1: Escludi Profili | AE1: NewProfileName | AF1: NewDevice | AG1: NewSignalName | AH1: NewSignalDescription | AI1: NewAlarmClass | AJ1: NewAlarmDescription | AK1: NewLogica | AL1: NewAddress | AM1: newRegister | AN1: newBitIndex | AO1: NewUOM | AP1: newSubplant | AQ1: NewCabina | AR1: NewQuadro | AS1: NewDirezione | AT1: NormalizedData | AU1: LeftOvers | AV1: extractedIds | AW1: <Used Functions> | AX1: Notice
A2: 10.220.80.16 | B2: CABINA PRINCIPALE | D2: PLC | E2: WATCHDOG | F2: HOLDING REGISTER | G2: Misura | H2: INT | I2: 999 | J2: WATCHDOG PLC (1s MAX 10000) | K2: 999 | N2: HOLDING REGISTER | O2: INT | P2: PLC WATCHDOG | R2: WATCHDOG PLC (1s MAX 10000) | U2: Misura | W2: CABINA PRINCIPALE | Z2: 10.220.80.16 | AA2: HOLDING_REGISTER | AB2: TWO_BYTE_INT_SIGNED | AC2: MIS | AE2: PLC-CAB | AF2: PLC--PLC1-MAX10000-CAB | AG2: MIS-WATCHDOG | AH2: Misura watchdog | AK2: 1s MAX 10000 | AL2: 999.0 | AM2: 999 | AN2: 0 | AQ2: CAB | AT2: MIS PLC WATCHDOG S CAB MAIN | AU2: PLC1 MAX10000 | AW2: ['Test 2b']
A3: 10.220.80.16 | B3: CABINA PRINCIPALE | C3: QRIF | D3: RIFASAMENTO AUTOMATICO | E3: QUADRO RIFASAMENTO | F3: HOLDING REGISTER | G3: Stato | H3: BOOL | I3: 1000.0 | J3: Rifasamento AUTOMATICOmatico -Sezionatore Chiuso | K3: 1000.0 | N3: HOLDING REGISTER | O3: BOOL | P3: RIFASAMENTO AUTOMATICO QUADRO RIFASAMENTO | R3: Rifasamento AUTOMATICOmatico -Sezionatore Chiuso | U3: Stato | V3: QRIF | W3: CABINA PRINCIPALE | Z3: 10.220.80.16 | AA3: HOLDING_REGISTER | AB3: BINARY | AC3: ST | AE3: QRIF-SEZ-CAB | AF3: QRIF-SEZ--MATICO-CAB | AG3: ST-SEZ | AH3: Stato sezionatore | AL3: 1000.0 | AM3: 1000 | AN3: 0 | AQ3: CAB | AR3: QRIF | AT3: ST RIFAS AUTO QUADR SEZ CH QRIF CAB MAIN | AU3: MATICO | AW3: ['Test 2b']
A4: 10.220.80.16 | B4: CABINA PRINCIPALE | C4: CENTRALINA | D4: RILIEVO INCENDI CABINA | E4: CENTRALINA RILIEVO INCENDI CABINA | F4: HOLDING REGISTER | G4: Allarme | H4: BOOL | I4: 1000.1 | J4: Centralina Rilievo Incendi Cabina -In Guasto | K4: 1000.1 | N4: HOLDING REGISTER | O4: BOOL | P4: RILIEVO INCENDI CABINA CENTRALINA RILIEVO INCENDI CABINA | R4: Centralina Rilievo Incendi Cabina -In Guasto | U4: Allarme | V4: CENTRALINA | W4: CABINA PRINCIPALE | Z4: 10.220.80.16 | AA4: HOLDING_REGISTER | AB4: BINARY | AC4: ALR | AE4: CNTRL-CAB-INCEND-RIL-CAB | AF4: CNTRL-CAB-INCEND-RIL--CAB | AG4: ALR-FAULT-CNTRL-RIL | AH4: Allarme guasto centralina rilevamento incendio | AL4: 1000.1 | AM4: 1000 | AN4: 1 | AQ4: CAB | AT4: ALR RIL INCEND CAB CNTRL IN FAULT MAIN | AW4: ['Test 1a']
A5: 10.220.80.16 | B5: CABINA PRINCIPALE | C5: CENTRALINA | D5: RILIEVO INCENDI CABINA | E5: CENTRALINA RILIEVO INCENDI CABINA | F5: HOLDING REGISTER | G5: Allarme | H5: BOOL | I5: 1000.2 | J5: Centralina Rilievo Incendi Cabina -Allarme Incendio | K5: 1000.2 | N5: HOLDING REGISTER | O5: BOOL | P5: RILIEVO INCENDI CABINA CENTRALINA RILIEVO INCENDI CABINA | R5: Centralina Rilievo Incendi Cabina -Allarme Incendio | U5: Allarme | V5: CENTRALINA | W5: CABINA PRINCIPALE | Z5: 10.220.80.16 | AA5: HOLDING_REGISTER | AB5: BINARY | AC5: ALR | AE5: CNTRL-CAB-INCEND-RIL-CAB | AF5: CNTRL-CAB-INCEND-RIL--CAB | AG5: ALR-CNTRL | AH5: Allarme centralina | AL5: 1000.2 | AM5: 1000 | AN5: 2 | AQ5: CAB | AT5: ALR RIL-INCEND RIL INCEND CAB CNTRL MAIN | AW5: ['Test 2b']
A6: 10.220.80.16 | B6: CABINA PRINCIPALE | C6: GRUPPO ELETTROGENO | D6: GRUPPO ELETTROGENO | E6: VANO G.E. | F6: HOLDING REGISTER | G6: Allarme | H6: BOOL | I6: 1000.3 | J6: Gruppo Elettrogeno -Allarme Generale | K6: 1000.3 | N6: HOLDING REGISTER | O6: BOOL | P6: GRUPPO ELETTROGENO VANO G.E. | R6: Gruppo Elettrogeno -Allarme Generale | U6: Allarme | V6: GRUPPO ELETTROGENO | W6: CABINA PRINCIPALE | Z6: 10.220.80.16 | AA6: HOLDING_REGISTER | AB6: BINARY | AC6: ALR | AE6: GE-CAB | AF6: GE--CAB | AG6: ALR-GENERALE-GE | AH6: Allarme generale G.E. | AL6: 1000.3 | AM6: 1000 | AN6: 3 | AQ6: CAB | AT6: ALR GE GROUP VANO G E GENERAL CAB MAIN | AW6: ['Test 2b']
A7: 10.220.80.16 | B7: CABINA PRINCIPALE | C7: GRUPPO ELETTROGENO | D7: GRUPPO ELETTROGENO | E7: VANO G.E. | F7: HOLDING REGISTER | G7: Stato | H7: BOOL | I7: 1000.4 | J7: Gruppo Elettrogeno -In Moto | K7: 1000.4 | N7: HOLDING REGISTER | O7: BOOL | P7: GRUPPO ELETTROGENO VANO G.E. | R7: Gruppo Elettrogeno -In Moto | U7: Stato | V7: GRUPPO ELETTROGENO | W7: CABINA PRINCIPALE | Z7: 10.220.80.16 | AA7: HOLDING_REGISTER | AB7: BINARY | AC7: ST | AE7: GE-CAB | AF7: GE--CAB | AG7: ALR-GE-RUN | AH7: Allarme G.E. in funzione | AL7: 1000.4 | AM7: 1000 | AN7: 4 | AQ7: CAB | AT7: GE ST GROUP VANO G E IN START CAB MAIN | AW7: ['Test 2b']
A8: 10.220.80.16 | B8: CABINA PRINCIPALE | C8: GRUPPO ELETTROGENO | D8: SERBATOIO | E8: SERBATOIO GASOLIO INTERRATO | F8: HOLDING REGISTER | G8: Allarme | H8: BOOL | I8: 1000.5 | J8: Serbatoio Gasolio Interrato -Perdite Serbatoio | K8: 1000.5 | N8: HOLDING REGISTER | O8: BOOL | P8: SERBATOIO SERBATOIO GASOLIO INTERRATO | R8: Serbatoio Gasolio Interrato -Perdite Serbatoio | U8: Allarme | V8: GRUPPO ELETTROGENO | W8: CABINA PRINCIPALE | Z8: 10.220.80.16 | AA8: HOLDING_REGISTER | AB8: BINARY | AC8: ALR | AE8: GE-CAB | AF8: GE--INTERRATO-CAB | AG8: ALR-FUEL-LOSS | AH8: Allarme perdita combustibile | AL8: 1000.5 | AM8: 1000 | AN8: 5 | AQ8: CAB | AT8: ALR GE SERBAT FUEL LOSS GROUP CAB MAIN | AU8: INTERRATO | AW8: ['Test 2b']
A9: 10.220.80.16 | B9: CABINA PRINCIPALE | C9: GRUPPO PRESSURIZZAZIONE | D9: GRUPPO PRESSURIZZAZIONE | E9: GRUPPO PRESSURIZZAZIONE | F9: HOLDING REGISTER | G9: Allarme | H9: BOOL | I9: 1000.6 | J9: Gruppo Pressurizzazione -Allarme A | K9: 1000.6 | N9: HOLDING REGISTER | O9: BOOL | P9: GRUPPO PRESSURIZZAZIONE GRUPPO PRESSURIZZAZIONE | R9: Gruppo Pressurizzazione -Allarme A | U9: Allarme | V9: GRUPPO PRESSURIZZAZIONE | W9: CABINA PRINCIPALE | Z9: 10.220.80.16 | AA9: HOLDING_REGISTER | AB9: BINARY | AC9: ALR | AE9: CAB | AF9: -CAB | AL9: 1000.6 | AM9: 1000 | AN9: 6 | AQ9: CAB | AT9: ALR GROUP PRESS A CAB MAIN
A10: 10.220.80.16 | B10: CABINA PRINCIPALE | C10: GRUPPO PRESSURIZZAZIONE | D10: GRUPPO PRESSURIZZAZIONE | E10: GRUPPO PRESSURIZZAZIONE | F10: HOLDING REGISTER | G10: Allarme | H10: BOOL | I10: 1000.7 | J10: Gruppo Pressurizzazione -Allarme B | K10: 1000.7 | N10: HOLDING REGISTER | O10: BOOL | P10: GRUPPO PRESSURIZZAZIONE GRUPPO PRESSURIZZAZIONE | R10: Gruppo Pressurizzazione -Allarme B | U10: Allarme | V10: GRUPPO PRESSURIZZAZIONE | W10: CABINA PRINCIPALE | Z10: 10.220.80.16 | AA10: HOLDING_REGISTER | AB10: BINARY | AC10: ALR | AE10: CAB | AF10: -CAB | AL10: 1000.7 | AM10: 1000 | AN10: 7 | AQ10: CAB | AT10: ALR GROUP PRESS B CAB MAIN
A11: 10.220.80.16 | B11: CABINA PRINCIPALE | C11: QMT | D11: INTERRUTTORE | E11: INTERRUTTORE | F11: HOLDING REGISTER | G11: Stato | H11: BOOL | I11: 1000.8 | J11: QMT -Interruttore Generale Chiuso | K11: 1000.8 | N11: HOLDING REGISTER | O11: BOOL | P11: INTERRUTTORE INTERRUTTORE | R11: QMT -Interruttore Generale Chiuso | U11: Stato | V11: QMT | W11: CABINA PRINCIPALE | Z11: 10.220.80.16 | AA11: HOLDING_REGISTER | AB11: BINARY | AC11: ST | AE11: QMT-INT-CAB | AF11: QMT-INT--CAB | AG11: ST-INT-CH | AH11: Stato interruttore chiuso | AL11: 1000.8 | AM11: 1000 | AN11: 8 | AQ11: CAB | AR11: QMT | AT11: ST INT QMT GENERAL CH CAB MAIN | AW11: ['Test 2b']
A12: 10.220.80.16 | B12: CABINA PRINCIPALE | C12: QMT | D12: INTERRUTTORE | E12: INTERRUTTORE | F12: HOLDING REGISTER | G12: Stato | H12: BOOL | I12: 1000.9 | J12: QMT -Interruttore Generale Aperto | K12: 1000.9 | N12: HOLDING REGISTER | O12: BOOL | P12: INTERRUTTORE INTERRUTTORE | R12: QMT -Interruttore Generale Aperto | U12: Stato | V12: QMT | W12: CABINA PRINCIPALE | Z12: 10.220.80.16 | AA12: HOLDING_REGISTER | AB12: BINARY | AC12: ST | AE12: QMT-INT-CAB | AF12: QMT-INT--CAB | AG12: ST-INT-AP | AH12: Stato interruttore aperto | AL12: 1000.9 | AM12: 1000 | AN12: 9 | AQ12: CAB | AR12: QMT | AT12: ST INT QMT GENERAL AP CAB MAIN | AW12: ['Test 2b']
A13: 10.220.80.16 | B13: CABINA PRINCIPALE | C13: QMT | D13: SEZIONATORE LINEA | E13: SEZIONATORE LINEA | F13: HOLDING REGISTER | G13: Stato | H13: BOOL | I13: 1000.10 | J13: QMT -Sezionatore Generale Di Linea Chiuso | K13: 1000.10 | N13: HOLDING REGISTER | O13: BOOL | P13: SEZIONATORE LINEA SEZIONATORE LINEA | R13: QMT -Sezionatore Generale Di Linea Chiuso | U13: Stato | V13: QMT | W13: CABINA PRINCIPALE | Z13: 10.220.80.16 | AA13: HOLDING_REGISTER | AB13: BINARY | AC13: ST | AE13: QMT-SEZ-CAB | AF13: QMT-SEZ--CAB | AG13: ST-SEZ-LINE-CH | AH13: Stato sezionatore linea chiuso | AL13: 1000.10 | AM13: 1000 | AN13: 10 | AQ13: CAB | AR13: QMT | AT13: ST SEZ LINE QMT GENERAL OF CH CAB MAIN | AW13: ['Test 2b']
A14: 10.220.80.16 | B14: CABINA PRINCIPALE | C14: QMT | D14: SEZIONATORE TERRA | E14: SEZIONATORE TERRA | F14: HOLDING REGISTER | G14: Stato | H14: BOOL | I14: 1000.11 | J14: QMT -Sezionatore Generale Di Terra Aperto | K14: 1000.11 | N14: HOLDING REGISTER | O14: BOOL | P14: SEZIONATORE TERRA SEZIONATORE TERRA | R14: QMT -Sezionatore Generale Di Terra Aperto | U14: Stato | V14: QMT | W14: CABINA PRINCIPALE | Z14: 10.220.80.16 | AA14: HOLDING_REGISTER | AB14: BINARY | AC14: ST | AE14: QMT-SEZ-CAB | AF14: QMT-SEZ--CAB | AG14: ST-SEZ-TERRA-AP | AH14: Stato sezionatore terra aperto | AL14: 1000.11 | AM14: 1000 | AN14: 11 | AQ14: CAB | AR14: QMT | AT14: ST SEZ TERRA QMT GENERAL OF AP CAB MAIN | AW14: ['Test 2b']
A15: 10.220.80.16 | B15: CABINA PRINCIPALE | C15: QMT | D15: INTERRUTTORE | E15: INTERRUTTORE | F15: HOLDING REGISTER | G15: Stato | H15: BOOL | I15: 1000.12 | J15: QMT -Interruttore TR1 Chiuso | K15: 1000.12 | N15: HOLDING REGISTER | O15: BOOL | P15: INTERRUTTORE INTERRUTTORE | R15: QMT -Interruttore TR1 Chiuso | U15: Stato | V15: QMT | W15: CABINA PRINCIPALE | Z15: 10.220.80.16 | AA15: HOLDING_REGISTER | AB15: BINARY | AC15: ST | AE15: QMT-INT-CAB | AF15: QMT-INT--CAB | AG15: ST-INT-CH | AH15: Stato interruttore chiuso | AL15: 1000.12 | AM15: 1000 | AN15: 12 | AQ15: CAB | AR15: QMT | AT15: ST INT QMT TRF1 CH CAB MAIN | AW15: ['Test 2b']
A16: 10.220.80.16 | B16: CABINA PRINCIPALE | C16: QMT | D16: INTERRUTTORE | E16: INTERRUTTORE | F16: HOLDING REGISTER | G16: Stato | H16: BOOL | I16: 1000.13 | J16: QMT -Interruttore TR1 Aperto | K16: 1000.13 | N16: HOLDING REGISTER | O16: BOOL | P16: INTERRUTTORE INTERRUTTORE | R16: QMT -Interruttore TR1 Aperto | U16: Stato | V16: QMT | W16: CABINA PRINCIPALE | Z16: 10.220.80.16 | AA16: HOLDING_REGISTER | AB16: BINARY | AC16: ST | AE16: QMT-INT-CAB | AF16: QMT-INT--CAB | AG16: ST-INT-AP | AH16: Stato interruttore aperto | AL16: 1000.13 | AM16: 1000 | AN16: 13 | AQ16: CAB | AR16: QMT | AT16: ST INT QMT TRF1 AP CAB MAIN | AW16: ['Test 2b']
A17: 10.220.80.16 | B17: CABINA PRINCIPALE | C17: QMT | D17: SEZIONATORE LINEA | E17: SEZIONATORE LINEA | F17: HOLDING REGISTER | G17: Stato | H17: BOOL | I17: 1000.14 | J17: QMT -Sezionatore Di Linea TR1 Chiuso | K17: 1000.14 | N17: HOLDING REGISTER | O17: BOOL | P17: SEZIONATORE LINEA SEZIONATORE LINEA | R17: QMT -Sezionatore Di Linea TR1 Chiuso | U17: Stato | V17: QMT | W17: CABINA PRINCIPALE | Z17: 10.220.80.16 | AA17: HOLDING_REGISTER | AB17: BINARY | AC17: ST | AE17: QMT-SEZ-CAB | AF17: QMT-SEZ--CAB | AG17: ST-SEZ-LINE-CH | AH17: Stato sezionatore linea chiuso | AL17: 1000.14 | AM17: 1000 | AN17: 14 | AQ17: CAB | AR17: QMT | AT17: ST SEZ LINE QMT OF TRF1 CH CAB MAIN | AW17: ['Test 2b']
A18: 10.220.80.16 | B18: CABINA PRINCIPALE | C18: QMT | D18: SEZIONATORE TERRA | E18: SEZIONATORE TERRA | F18: HOLDING REGISTER | G18: Stato | H18: BOOL | I18: 1000.15 | J18: QMT -Sezionatore Di Terra TR1 Aperto | K18: 1000.15 | N18: HOLDING REGISTER | O18: BOOL | P18: SEZIONATORE TERRA SEZIONATORE TERRA | R18: QMT -Sezionatore Di Terra TR1 Aperto | U18: Stato | V18: QMT | W18: CABINA PRINCIPALE | Z18: 10.220.80.16 | AA18: HOLDING_REGISTER | AB18: BINARY | AC18: ST | AE18: QMT-SEZ-CAB | AF18: QMT-SEZ--CAB | AG18: ST-SEZ-TERRA-AP | AH18: Stato sezionatore terra aperto | AL18: 1000.15 | AM18: 1000 | AN18: 15 | AQ18: CAB | AR18: QMT | AT18: ST SEZ TERRA QMT OF TRF1 AP CAB MAIN | AW18: ['Test 2b']
A19: 10.220.80.16 | B19: CABINA PRINCIPALE | C19: QMT | D19: INTERRUTTORE | E19: INTERRUTTORE | F19: HOLDING REGISTER | G19: Stato | H19: BOOL | I19: 1001.0 | J19: QMT -Interruttore TR2 Chiuso | K19: 1001.0 | N19: HOLDING REGISTER | O19: BOOL | P19: INTERRUTTORE INTERRUTTORE | R19: QMT -Interruttore TR2 Chiuso | U19: Stato | V19: QMT | W19: CABINA PRINCIPALE | Z19: 10.220.80.16 | AA19: HOLDING_REGISTER | AB19: BINARY | AC19: ST | AE19: QMT-INT-CAB | AF19: QMT-INT--CAB | AG19: ST-INT-CH | AH19: Stato interruttore chiuso | AL19: 1001.0 | AM19: 1001 | AN19: 0 | AQ19: CAB | AR19: QMT | AT19: ST INT QMT TRF2 CH CAB MAIN | AW19: ['Test 2b']
A20: 10.220.80.16 | B20: CABINA PRINCIPALE | C20: QMT | D20: INTERRUTTORE | E20: INTERRUTTORE | F20: HOLDING REGISTER | G20: Stato | H20: BOOL | I20: 1001.1 | J20: QMT -Interruttore TR2 Aperto | K20: 1001.1 | N20: HOLDING REGISTER | O20: BOOL | P20: INTERRUTTORE INTERRUTTORE | R20: QMT -Interruttore TR2 Aperto | U20: Stato | V20: QMT | W20: CABINA PRINCIPALE | Z20: 10.220.80.16 | AA20: HOLDING_REGISTER | AB20: BINARY | AC20: ST | AE20: QMT-INT-CAB | AF20: QMT-INT--CAB | AG20: ST-INT-AP | AH20: Stato interruttore aperto | AL20: 1001.1 | AM20: 1001 | AN20: 1 | AQ20: CAB | AR20: QMT | AT20: ST INT QMT TRF2 AP CAB MAIN | AW20: ['Test 2b']
A21: 10.220.80.16 | B21: CABINA PRINCIPALE | C21: QMT | D21: SEZIONATORE LINEA | E21: SEZIONATORE LINEA | F21: HOLDING REGISTER | G21: Stato | H21: BOOL | I21: 1001.2 | J21: QMT -Sezionatore Di Linea TR2 Chiuso | K21: 1001.2 | N21: HOLDING REGISTER | O21: BOOL | P21: SEZIONATORE LINEA SEZIONATORE LINEA | R21: QMT -Sezionatore Di Linea TR2 Chiuso | U21: Stato | V21: QMT | W21: CABINA PRINCIPALE | Z21: 10.220.80.16 | AA21: HOLDING_REGISTER | AB21: BINARY | AC21: ST | AE21: QMT-SEZ-CAB | AF21: QMT-SEZ--CAB | AG21: ST-SEZ-LINE-CH | AH21: Stato sezionatore linea chiuso | AL21: 1001.2 | AM21: 1001 | AN21: 2 | AQ21: CAB | AR21: QMT | AT21: ST SEZ LINE QMT OF TRF2 CH CAB MAIN | AW21: ['Test 2b']
A22: 10.220.80.16 | B22: CABINA PRINCIPALE | C22: QMT | D22: SEZIONATORE TERRA | E22: SEZIONATORE TERRA | F22: HOLDING REGISTER | G22: Stato | H22: BOOL | I22: 1001.3 | J22: QMT -Sezionatore Di Terra TR2 Aperto | K22: 1001.3 | N22: HOLDING REGISTER | O22: BOOL | P22: SEZIONATORE TERRA SEZIONATORE TERRA | R22: QMT -Sezionatore Di Terra TR2 Aperto | U22: Stato | V22: QMT | W22: CABINA PRINCIPALE | Z22: 10.220.80.16 | AA22: HOLDING_REGISTER | AB22: BINARY | AC22: ST | AE22: QMT-SEZ-CAB | AF22: QMT-SEZ--CAB | AG22: ST-SEZ-TERRA-AP | AH22: Stato sezionatore terra aperto | AL22: 1001.3 | AM22: 1001 | AN22: 3 | AQ22: CAB | AR22: QMT | AT22: ST SEZ TERRA QMT OF TRF2 AP CAB MAIN | AW22: ['Test 2b']
... A25: 10.220.80.16 | B25: CABINA PRINCIPALE | C25: TRAFO 2 | D25: CENTRALINA CONTROLLO TEMPERATURA | E25: TR2 | F25: HOLDING REGISTER | G25: Allarme | H25: BOOL | I25: 1001.6 | J25: QMT -Guasto Centralina Temperatura TR2 | K25: 1001.6 | N25: HOLDING REGISTER | O25: BOOL | P25: CENTRALINA CONTROLLO TEMPERATURA TR2 | R25: QMT -Guasto Centralina Temperatura TR2 | U25: Allarme | V25: TRAFO 2 | W25: CABINA PRINCIPALE | Z25: 10.220.80.16 | AA25: HOLDING_REGISTER | AB25: BINARY | AC25: ALR | AE25: QMT-TRF2-CNTRL-CAB | AF25: QMT-TRF2-CNTRL--CAB | AG25: ALR-FAULT-CNTRL | AH25: Allarme guasto centralina | AL25: 1001.6 | AM25: 1001 | AN25: 6 | AQ25: CAB | AR25: QMT | AT25: ALR CNTRL CMD TEMP TRF2 QMT FAULT CAB MAIN | AW25: ['Test 1a']
A26: 10.220.80.16 | B26: CABINA PRINCIPALE | C26: TRAFO 2 | D26: CENTRALINA CONTROLLO TEMPERATURA | E26: TR2 | F26: HOLDING REGISTER | G26: Allarme | H26: BOOL | I26: 1001.7 | J26: QMT -Allarme Temperatura TR2 | K26: 1001.7 | N26: HOLDING REGISTER | O26: BOOL | P26: CENTRALINA CONTROLLO TEMPERATURA TR2 | R26: QMT -Allarme Temperatura TR2 | U26: Allarme | V26: TRAFO 2 | W26: CABINA PRINCIPALE | Z26: 10.220.80.16 | AA26: HOLDING_REGISTER | AB26: BINARY | AC26: ALR | AE26: QMT-TRF2-CNTRL-CAB | AF26: QMT-TRF2-CNTRL--CAB | AL26: 1001.7 | AM26: 1001 | AN26: 7 | AQ26: CAB | AR26: QMT | AT26: ALR CNTRL CMD TEMP TRF2 QMT CAB MAIN
A27: 10.220.80.16 | B27: CABINA PRINCIPALE | C27: QGBT1 | D27: INTERRUTTORE | E27: 1 | F27: HOLDING REGISTER | G27: Stato | H27: BOOL | I27: 1001.8 | J27: QGBT1 -INTERRUTTORE RIFASAMENTO FISSO TRAFO 1 400Vac CHIUSO | K27: 1001.8 | N27: HOLDING REGISTER | O27: BOOL | P27: INTERRUTTORE 1 | R27: QGBT1 -INTERRUTTORE RIFASAMENTO FISSO TRAFO 1 400Vac CHIUSO | U27: Stato | V27: QGBT1 | W27: CABINA PRINCIPALE | Z27: 10.220.80.16 | AA27: HOLDING_REGISTER | AB27: BINARY | AC27: ST | AE27: QGBT1-INT-CAB | AF27: QGBT1-INT--FISSO-INTERRUTTORE1-CAB | AG27: ST-INT-CH | AH27: Stato interruttore chiuso | AL27: 1001.8 | AM27: 1001 | AN27: 8 | AQ27: CAB | AR27: QGBT1 | AT27: 400V ST QGBT1 INT RIFAS TRF1 AC CH CAB MAIN | AU27: FISSO INTERRUTTORE1 | AW27: ['Test 2b']
A28: 10.220.80.16 | B28: CABINA PRINCIPALE | C28: QGBT1 | D28: INTERRUTTORE | E28: 1 | F28: HOLDING REGISTER | G28: Allarme | H28: BOOL | I28: 1001.9 | J28: QGBT1 -INTERRUTTORE RIFASAMENTO FISSO TRAFO 1 400Vac SCATTATO | K28: 1001.9 | N28: HOLDING REGISTER | O28: BOOL | P28: INTERRUTTORE 1 | R28: QGBT1 -INTERRUTTORE RIFASAMENTO FISSO TRAFO 1 400Vac SCATTATO | U28: Allarme | V28: QGBT1 | W28: CABINA PRINCIPALE | Z28: 10.220.80.16 | AA28: HOLDING_REGISTER | AB28: BINARY | AC28: ALR | AE28: QGBT1-INT-CAB | AF28: QGBT1-INT--FISSO-INTERRUTTORE1-CAB | AG28: ALR-INT-SCATT | AH28: Allarme interruttore scattato | AL28: 1001.9 | AM28: 1001 | AN28: 9 | AQ28: CAB | AR28: QGBT1 | AT28: 400V ALR QGBT1 INT RIFAS TRF1 AC SCATT CAB MAIN | AU28: FISSO INTERRUTTORE1 | AW28: ['Test 1a']
A29: 10.220.80.16 | B29: CABINA PRINCIPALE | C29: QGBT1 | D29: SCARICATORE SOVRATENSIONI | E29: SPD1 | F29: HOLDING REGISTER | G29: Allarme | H29: BOOL | I29: 1001.10 | J29: QGBT1 -LIMITATORE DI SOVRATENSIONE INTERVENUTO TRAFO 1 400Vac | K29: 1001.10 | N29: HOLDING REGISTER | O29: BOOL | P29: SCARICATORE SOVRATENSIONI SPD1 | R29: QGBT1 -LIMITATORE DI SOVRATENSIONE INTERVENUTO TRAFO 1 400Vac | U29: Allarme | V29: QGBT1 | W29: CABINA PRINCIPALE | Z29: 10.220.80.16 | AA29: HOLDING_REGISTER | AB29: BINARY | AC29: ALR | AE29: QGBT1-SCAR-CAB | AF29: QGBT1-SCAR--SPD1-LIMITATORE-CAB | AG29: ALR-SCAR | AH29: Allarme scaricatore | AL29: 1001.10 | AM29: 1001 | AN29: 10 | AQ29: CAB | AR29: QGBT1 | AT29: 400V ALR SCAR SOVRATENS QGBT1 OF INTERV TRF1 AC CAB MAIN | AU29: SPD1 LIMITATORE | AW29: ['Test 2b']
A30: 10.220.80.16 | B30: CABINA PRINCIPALE | C30: QGBT1 | D30: INTERRUTTORE | E30: 2 | F30: HOLDING REGISTER | G30: Stato | H30: BOOL | I30: 1001.11 | J30: QGBT1 -INTERRUTTORE GENERALE TRAFO 1 400Vac CHIUSO | K30: 1001.11 | N30: HOLDING REGISTER | O30: BOOL | P30: INTERRUTTORE 2 | R30: QGBT1 -INTERRUTTORE GENERALE TRAFO 1 400Vac CHIUSO | U30: Stato | V30: QGBT1 | W30: CABINA PRINCIPALE | Z30: 10.220.80.16 | AA30: HOLDING_REGISTER | AB30: BINARY | AC30: ST | AE30: QGBT1-INT-CAB | AF30: QGBT1-INT--INTERRUTTORE2-CAB | AG30: ST-INT-CH | AH30: Stato interruttore chiuso | AL30: 1001.11 | AM30: 1001 | AN30: 11 | AQ30: CAB | AR30: QGBT1 | AT30: 400V ST QGBT1 INT GENERAL TRF1 AC CH CAB MAIN | AU30: INTERRUTTORE2 | AW30: ['Test 2b']
A31: 10.220.80.16 | B31: CABINA PRINCIPALE | C31: QGBT1 | D31: INTERRUTTORE | E31: 2 | F31: HOLDING REGISTER | G31: Allarme | H31: BOOL | I31: 1001.12 | J31: QGBT1 -INTERRUTTORE GENERALE TRAFO 1 400Vac SCATTATO | K31: 1001.12 | N31: HOLDING REGISTER | O31: BOOL | P31: INTERRUTTORE 2 | R31: QGBT1 -INTERRUTTORE GENERALE TRAFO 1 400Vac SCATTATO | U31: Allarme | V31: QGBT1 | W31: CABINA PRINCIPALE | Z31: 10.220.80.16 | AA31: HOLDING_REGISTER | AB31: BINARY | AC31: ALR | AE31: QGBT1-INT-CAB | AF31: QGBT1-INT--INTERRUTTORE2-CAB | AG31: ALR-INT-SCATT | AH31: Allarme interruttore scattato | AL31: 1001.12 | AM31: 1001 | AN31: 12 | AQ31: CAB | AR31: QGBT1 | AT31: 400V ALR QGBT1 INT GENERAL TRF1 AC SCATT CAB MAIN | AU31: INTERRUTTORE2 | AW31: ['Test 1a']
A32: 10.220.80.16 | B32: CABINA PRINCIPALE | C32: QGBT1 | D32: INTERRUTTORE | E32: 3 | F32: HOLDING REGISTER | G32: Stato | H32: BOOL | I32: 1001.13 | J32: QGBT1 -INTERRUTTORE RIFASAMENTO FISSO TRAFO 2 400Vac CHIUSO | K32: 1001.13 | N32: HOLDING REGISTER | O32: BOOL | P32: INTERRUTTORE 3 | R32: QGBT1 -INTERRUTTORE RIFASAMENTO FISSO TRAFO 2 400Vac CHIUSO | U32: Stato | V32: QGBT1 | W32: CABINA PRINCIPALE | Z32: 10.220.80.16 | AA32: HOLDING_REGISTER | AB32: BINARY | AC32: ST | AE32: QGBT1-INT-CAB | AF32: QGBT1-INT--FISSO-INTERRUTTORE3-CAB | AG32: ST-INT-CH | AH32: Stato interruttore chiuso | AL32: 1001.13 | AM32: 1001 | AN32: 13 | AQ32: CAB | AR32: QGBT1 | AT32: 400V ST QGBT1 INT RIFAS TRF2 AC CH CAB MAIN | AU32: FISSO INTERRUTTORE3 | AW32: ['Test 2b']
A33: 10.220.80.16 | B33: CABINA PRINCIPALE | C33: QGBT1 | D33: INTERRUTTORE | E33: 3 | F33: HOLDING REGISTER | G33: Allarme | H33: BOOL | I33: 1001.14 | J33: QGBT1 -INTERRUTTORE RIFASAMENTO FISSO TRAFO 2 400Vac SCATTATO | K33: 1001.14 | N33: HOLDING REGISTER | O33: BOOL | P33: INTERRUTTORE 3 | R33: QGBT1 -INTERRUTTORE RIFASAMENTO FISSO TRAFO 2 400Vac SCATTATO | U33: Allarme | V33: QGBT1 | W33: CABINA PRINCIPALE | Z33: 10.220.80.16 | AA33: HOLDING_REGISTER | AB33: BINARY | AC33: ALR | AE33: QGBT1-INT-CAB | AF33: QGBT1-INT--FISSO-INTERRUTTORE3-CAB | AG33: ALR-INT-SCATT | AH33: Allarme interruttore scattato | AL33: 1001.14 | AM33: 1001 | AN33: 14 | AQ33: CAB | AR33: QGBT1 | AT33: 400V ALR QGBT1 INT RIFAS TRF2 AC SCATT CAB MAIN | AU33: FISSO INTERRUTTORE3 | AW33: ['Test 1a']
A34: 10.220.80.16 | B34: CABINA PRINCIPALE | C34: QGBT1 | D34: SCARICATORE SOVRATENSIONI | E34: SPD2 | F34: HOLDING REGISTER | G34: Allarme | H34: BOOL | I34: 1001.15 | J34: QGBT1 -LIMITATORE DI SOVRATENSIONE INTERVENUTO TRAFO 2 400Vac | K34: 1001.15 | N34: HOLDING REGISTER | O34: BOOL | P34: SCARICATORE SOVRATENSIONI SPD2 | R34: QGBT1 -LIMITATORE DI SOVRATENSIONE INTERVENUTO TRAFO 2 400Vac | U34: Allarme | V34: QGBT1 | W34: CABINA PRINCIPALE | Z34: 10.220.80.16 | AA34: HOLDING_REGISTER | AB34: BINARY | AC34: ALR | AE34: QGBT1-SCAR-CAB | AF34: QGBT1-SCAR--SPD2-LIMITATORE-CAB | AG34: ALR-SCAR | AH34: Allarme scaricatore | AL34: 1001.15 | AM34: 1001 | AN34: 15 | AQ34: CAB | AR34: QGBT1 | AT34: 400V ALR SCAR SOVRATENS QGBT1 OF INTERV TRF2 AC CAB MAIN | AU34: SPD2 LIMITATORE | AW34: ['Test 2b']
A35: 10.220.80.16 | B35: CABINA PRINCIPALE | C35: QGBT1 | D35: INTERRUTTORE | E35: 4 | F35: HOLDING REGISTER | G35: Stato | H35: BOOL | I35: 1002.0 | J35: QGBT1 -INTERRUTTORE GENERALE TRAFO 2 400Vac CHIUSO | K35: 1002.0 | N35: HOLDING REGISTER | O35: BOOL | P35: INTERRUTTORE 4 | R35: QGBT1 -INTERRUTTORE GENERALE TRAFO 2 400Vac CHIUSO | U35: Stato | V35: QGBT1 | W35: CABINA PRINCIPALE | Z35: 10.220.80.16 | AA35: HOLDING_REGISTER | AB35: BINARY | AC35: ST | AE35: QGBT1-INT-CAB | AF35: QGBT1-INT--INTERRUTTORE4-CAB | AG35: ST-INT-CH | AH35: Stato interruttore chiuso | AL35: 1002.0 | AM35: 1002 | AN35: 0 | AQ35: CAB | AR35: QGBT1 | AT35: 400V ST QGBT1 INT GENERAL TRF2 AC CH CAB MAIN | AU35: INTERRUTTORE4 | AW35: ['Test 2b']
A36: 10.220.80.16 | B36: CABINA PRINCIPALE | C36: QGBT1 | D36: INTERRUTTORE | E36: 4 | F36: HOLDING REGISTER | G36: Allarme | H36: BOOL | I36: 1002.1 | J36: QGBT1 -INTERRUTTORE GENERALE TRAFO 2 400Vac SCATTATO | K36: 1002.1 | N36: HOLDING REGISTER | O36: BOOL | P36: INTERRUTTORE 4 | R36: QGBT1 -INTERRUTTORE GENERALE TRAFO 2 400Vac SCATTATO | U36: Allarme | V36: QGBT1 | W36: CABINA PRINCIPALE | Z36: 10.220.80.16 | AA36: HOLDING_REGISTER | AB36: BINARY | AC36: ALR | AE36: QGBT1-INT-CAB | AF36: QGBT1-INT--INTERRUTTORE4-CAB | AG36: ALR-INT-SCATT | AH36: Allarme interruttore scattato | AL36: 1002.1 | AM36: 1002 | AN36: 1 | AQ36: CAB | AR36: QGBT1 | AT36: 400V ALR QGBT1 INT GENERAL TRF2 AC SCATT CAB MAIN | AU36: INTERRUTTORE4 | AW36: ['Test 1a']
A37: 10.220.80.16 | B37: CABINA PRINCIPALE | C37: QGBT1 | D37: INTERRUTTORE | E37: 6 | F37: HOLDING REGISTER | G37: Stato | H37: BOOL | I37: 1002.2 | J37: QGBT1 -INTERRUTTORE ELETTROPOMPA ANTINCENDIO CHIUSO | K37: 1002.2 | N37: HOLDING REGISTER | O37: BOOL | P37: INTERRUTTORE 6 | R37: QGBT1 -INTERRUTTORE ELETTROPOMPA ANTINCENDIO CHIUSO | U37: Stato | V37: QGBT1 | W37: CABINA PRINCIPALE | Z37: 10.220.80.16 | AA37: HOLDING_REGISTER | AB37: BINARY | AC37: ST | AE37: QGBT1-INT-CAB | AF37: QGBT1-INT--INTERRUTTORE6-CAB | AG37: ST-INT-CH | AH37: Stato interruttore chiuso | AL37: 1002.2 | AM37: 1002 | AN37: 2 | AQ37: CAB | AR37: QGBT1 | AT37: ST QGBT1 INT EPUMP ANTINC CH CAB MAIN | AU37: INTERRUTTORE6 | AW37: ['Test 2b']
A38: 10.220.80.16 | B38: CABINA PRINCIPALE | C38: QGBT1 | D38: INTERRUTTORE | E38: 6 | F38: HOLDING REGISTER | G38: Allarme | H38: BOOL | I38: 1002.3 | J38: QGBT1 -INTERRUTTORE ELETTROPOMPA ANTINCENDIO SCATTATO | K38: 1002.3 | N38: HOLDING REGISTER | O38: BOOL | P38: INTERRUTTORE 6 | R38: QGBT1 -INTERRUTTORE ELETTROPOMPA ANTINCENDIO SCATTATO | U38: Allarme | V38: QGBT1 | W38: CABINA PRINCIPALE | Z38: 10.220.80.16 | AA38: HOLDING_REGISTER | AB38: BINARY | AC38: ALR | AE38: QGBT1-INT-CAB | AF38: QGBT1-INT--INTERRUTTORE6-CAB | AG38: ALR-INT-SCATT | AH38: Allarme interruttore scattato | AL38: 1002.3 | AM38: 1002 | AN38: 3 | AQ38: CAB | AR38: QGBT1 | AT38: ALR QGBT1 INT EPUMP ANTINC SCATT CAB MAIN | AU38: INTERRUTTORE6 | AW38: ['Test 1a']
... A49: 10.220.80.16 | B49: CABINA PRINCIPALE | C49: QGBT1 | D49: CENTRALINA COMMUTAZIONE RETE/GE | E49: 10BA1 | F49: HOLDING REGISTER | G49: Stato | H49: BOOL | I49: 1002.14 | J49: QGBT1 -CENTRALINA SCAMBIO RETE/G.E. IN AUTOMATICOMATICO | K49: 1002.14 | N49: HOLDING REGISTER | O49: BOOL | P49: CENTRALINA COMMUTAZIONE RETE/GE 10BA1 | R49: QGBT1 -CENTRALINA SCAMBIO RETE/G.E. IN AUTOMATICOMATICO | U49: Stato | V49: QGBT1 | W49: CABINA PRINCIPALE | Z49: 10.220.80.16 | AA49: HOLDING_REGISTER | AB49: BINARY | AC49: ST | AE49: QGBT1-GE-CNTRL-RETE-CAB | AF49: QGBT1-GE-CNTRL-RETE--GE10-BA1-CAB | AG49: ST-SELETT-AUTO | AH49: Stato funzionamento in automatico | AL49: 1002.14 | AM49: 1002 | AN49: 14 | AQ49: CAB | AR49: QGBT1 | AT49: GE ST CNTRL COMMUT RETE QGBT1 REPLACE G E IN AUTO CAB MAIN | AU49: GE10 BA1 | AW49: ['Test 2b']
A50: 10.220.80.16 | B50: CABINA PRINCIPALE | C50: QGBT1 | D50: INTERRUTTORE | E50: 22 | F50: HOLDING REGISTER | G50: Stato | H50: BOOL | I50: 1002.15 | J50: QGBT1 -INTERRUTTORE RIFASAMENTO AUTOMATICOMATICO CHIUSO | K50: 1002.15 | N50: HOLDING REGISTER | O50: BOOL | P50: INTERRUTTORE 22 | R50: QGBT1 -INTERRUTTORE RIFASAMENTO AUTOMATICOMATICO CHIUSO | U50: Stato | V50: QGBT1 | W50: CABINA PRINCIPALE | Z50: 10.220.80.16 | AA50: HOLDING_REGISTER | AB50: BINARY | AC50: ST | AE50: QGBT1-INT-CAB | AF50: QGBT1-INT--INTERRUTTORE22-CAB | AL50: 1002.15 | AM50: 1002 | AN50: 15 | AQ50: CAB | AR50: QGBT1 | AT50: ST QGBT1 INT RIFAS AUTO CH CAB MAIN | AU50: INTERRUTTORE22
A51: 10.220.80.16 | B51: CABINA PRINCIPALE | C51: QGBT1 | D51: INTERRUTTORE | E51: 22 | F51: HOLDING REGISTER | G51: Allarme | H51: BOOL | I51: 1003.0 | J51: QGBT1 -INTERRUTTORE RIFASAMENTO AUTOMATICOMATICO SCATTATO | K51: 1003.0 | N51: HOLDING REGISTER | O51: BOOL | P51: INTERRUTTORE 22 | R51: QGBT1 -INTERRUTTORE RIFASAMENTO AUTOMATICOMATICO SCATTATO | U51: Allarme | V51: QGBT1 | W51: CABINA PRINCIPALE | Z51: 10.220.80.16 | AA51: HOLDING_REGISTER | AB51: BINARY | AC51: ALR | AE51: QGBT1-INT-CAB | AF51: QGBT1-INT--INTERRUTTORE22-CAB | AG51: ALR-INT-SCATT | AH51: Allarme interruttore scattato | AL51: 1003.0 | AM51: 1003 | AN51: 0 | AQ51: CAB | AR51: QGBT1 | AT51: ALR QGBT1 INT RIFAS AUTO SCATT CAB MAIN | AU51: INTERRUTTORE22 | AW51: ['Test 1a']
A52: 10.220.80.16 | B52: CABINA PRINCIPALE | C52: QGBT1 | D52: INTERRUTTORE | E52: 23 | F52: HOLDING REGISTER | G52: Stato | H52: BOOL | I52: 1003.1 | J52: QGBT1 -INTERRUTTORE QGBT2 CASOLA CHIUSO | K52: 1003.1 | N52: HOLDING REGISTER | O52: BOOL | P52: INTERRUTTORE 23 | R52: QGBT1 -INTERRUTTORE QGBT2 CASOLA CHIUSO | U52: Stato | V52: QGBT1 | W52: CABINA PRINCIPALE | Z52: 10.220.80.16 | AA52: HOLDING_REGISTER | AB52: BINARY | AC52: ST | AE52: QGBT1-INT-CAB | AF52: QGBT1-INT--INTERRUTTORE23-CASOLA-CAB | AG52: ST-INT-CH | AH52: Stato interruttore chiuso | AL52: 1003.1 | AM52: 1003 | AN52: 1 | AQ52: CAB | AR52: QGBT1 | AT52: ST QGBT1 INT QGBT2 CH CAB MAIN | AU52: INTERRUTTORE23 CASOLA | AW52: ['Test 2b']
...

Sheet Import
A1: deviceId | B1: deviceName | C1: signalName | D1: profileName | E1: datasourceName | F1: driverId | G1: driverInstance | H1: disabled | I1: signalDescription | J1: register | K1: registerType | L1: dataType | M1: offset | N1: slaveId | O1: bitIndex | P1: registerCount | Q1: bitMask
A2: =WIP!AD2 -> 0 | B2: =WIP!AF2 -> PLC--PLC1-MAX10000-CAB | C2: =WIP!AG2 -> MIS-WATCHDOG | D2: =WIP!AE2 -> PLC-CAB | H2: false | K2: =WIP!AA2 -> HOLDING_REGISTER | L2: =WIP!AB2 -> TWO_BYTE_INT_SIGNED | M2: 0 | N2: 1 | P2: 1 | Q2: 0000000000000000
A3: =WIP!AD3 -> 0 | B3: =WIP!AF3 -> QRIF-SEZ--MATICO-CAB | C3: =WIP!AG3 -> ST-SEZ | D3: =WIP!AE3 -> QRIF-SEZ-CAB | H3: false | K3: =WIP!AA3 -> HOLDING_REGISTER | L3: =WIP!AB3 -> BINARY | M3: 0 | N3: 1 | P3: 1 | Q3: 0000000000000000
A4: =WIP!AD4 -> 0 | B4: =WIP!AF4 -> CNTRL-CAB-INCEND-RIL--CAB | C4: =WIP!AG4 -> ALR-FAULT-CNTRL-RIL | D4: =WIP!AE4 -> CNTRL-CAB-INCEND-RIL-CAB | H4: false | K4: =WIP!AA4 -> HOLDING_REGISTER | L4: =WIP!AB4 -> BINARY | M4: 0 | N4: 1 | P4: 1 | Q4: 0000000000000000
A5: =WIP!AD5 -> 0 | B5: =WIP!AF5 -> CNTRL-CAB-INCEND-RIL--CAB | C5: =WIP!AG5 -> ALR-CNTRL | D5: =WIP!AE5 -> CNTRL-CAB-INCEND-RIL-CAB | H5: false | K5: =WIP!AA5 -> HOLDING_REGISTER | L5: =WIP!AB5 -> BINARY | M5: 0 | N5: 1 | P5: 1 | Q5: 0000000000000000
A6: =WIP!AD6 -> 0 | B6: =WIP!AF6 -> GE--CAB | C6: =WIP!AG6 -> ALR-GENERALE-GE | D6: =WIP!AE6 -> GE-CAB | H6: false | K6: =WIP!AA6 -> HOLDING_REGISTER | L6: =WIP!AB6 -> BINARY | M6: 0 | N6: 1 | P6: 1 | Q6: 0000000000000000
A7: =WIP!AD7 -> 0 | B7: =WIP!AF7 -> GE--CAB | C7: =WIP!AG7 -> ALR-GE-RUN | D7: =WIP!AE7 -> GE-CAB | H7: false | K7: =WIP!AA7 -> HOLDING_REGISTER | L7: =WIP!AB7 -> BINARY | M7: 0 | N7: 1 | P7: 1 | Q7: 0000000000000000
A8: =WIP!AD8 -> 0 | B8: =WIP!AF8 -> GE--INTERRATO-CAB | C8: =WIP!AG8 -> ALR-FUEL-LOSS | D8: =WIP!AE8 -> GE-CAB | H8: false | K8: =WIP!AA8 -> HOLDING_REGISTER | L8: =WIP!AB8 -> BINARY | M8: 0 | N8: 1 | P8: 1 | Q8: 0000000000000000
A9: =WIP!AD9 -> 0 | B9: =WIP!AF9 -> -CAB | C9: =WIP!AG9 -> 0 | D9: =WIP!AE9 -> CAB | H9: false | K9: =WIP!AA9 -> HOLDING_REGISTER | L9: =WIP!AB9 -> BINARY | M9: 0 | N9: 1 | P9: 1 | Q9: 0000000000000000
A10: =WIP!AD10 -> 0 | B10: =WIP!AF10 -> -CAB | C10: =WIP!AG10 -> 0 | D10: =WIP!AE10 -> CAB | H10: false | K10: =WIP!AA10 -> HOLDING_REGISTER | L10: =WIP!AB10 -> BINARY | M10: 0 | N10: 1 | P10: 1 | Q10: 0000000000000000
A11: =WIP!AD11 -> 0 | B11: =WIP!AF11 -> QMT-INT--CAB | C11: =WIP!AG11 -> ST-INT-CH | D11: =WIP!AE11 -> QMT-INT-CAB | H11: false | K11: =WIP!AA11 -> HOLDING_REGISTER | L11: =WIP!AB11 -> BINARY | M11: 0 | N11: 1 | P11: 1 | Q11: 0000000000000000
A12: =WIP!AD12 -> 0 | B12: =WIP!AF12 -> QMT-INT--CAB | C12: =WIP!AG12 -> ST-INT-AP | D12: =WIP!AE12 -> QMT-INT-CAB | H12: false | K12: =WIP!AA12 -> HOLDING_REGISTER | L12: =WIP!AB12 -> BINARY | M12: 0 | N12: 1 | P12: 1 | Q12: 0000000000000000
A13: =WIP!AD13 -> 0 | B13: =WIP!AF13 -> QMT-SEZ--CAB | C13: =WIP!AG13 -> ST-SEZ-LINE-CH | D13: =WIP!AE13 -> QMT-SEZ-CAB | H13: false | K13: =WIP!AA13 -> HOLDING_REGISTER | L13: =WIP!AB13 -> BINARY | M13: 0 | N13: 1 | P13: 1 | Q13: 0000000000000000
... A248: =WIP!AD248 -> 0 | B248: =WIP!AF248 -> QIS2-INT--INTERRUTTORE31-CAB | C248: =WIP!AG248 -> ST-INT-CH | D248: =WIP!AE248 -> QIS2-INT-CAB | H248: false | K248: =WIP!AA248 -> HOLDING_REGISTER | L248: =WIP!AB248 -> BINARY | M248: 0 | N248: 1 | P248: 1 | Q248: 0000000000000000
